Workbook

Sheet BASE_PAGAMENTOS
A1: Tipo/NroDocto | B1: Tipo/NroCartão | C1: Embarque | D1: Pagamento | E1: Tipo | F1: Valor Transação | G1: Status | H1: Nome do Favorecido | I1: Documento do Favorecido | J1: Placa do veículo | K1: ID Viagem | L1: Filial | M1: Contrato de Frete | N1: Carga | O1: CT´es | P1: UF Filial | Q1: UF Destino | R1: Situação da CF | S1: Situação da carga | T1: Status Financeiro | U1: Prazo | V1: DT de pagamento | W1: Cont_caracter | X1: DEF_PRESTADOR | Y1: REFERENCIA | Z1: PRESTADOR | AA1: Email_transp
A2: CON:277 | B2: 4417812014686304 | C2: 45833 | D2: 45833 | E2: ADT | F2: 300 | G2: EFETIVADA | H2: SILVERIO DA SILVEIRA | I2: 17250059000130 | J2: ATL5J69 | K2: 100902598 | L2: SP | M2: 144264 | N2: 262876 | O2: 277 | P2: RS | Q2: RS | R2: Finalizado | S2: Finalizada | T2: EFETIVADA | U2: Quinta feira | V2: Quinta feira | W2: =LEN(I2) -> 14 | X2: =IF(W2=14,"CNPJ",IF(W2=12,"CNPJ_INCOMPLETO_2",IF(W2=13,"CNPJ_INCOMPLETO_1",IF(W2=10,"CPF_Incompleto","CPF")))) -> CNPJ | Y2: =IF(X2="CNPJ_INCOMPLETO_1",("0"&LEFT(I2,1)&"."&MID(I2,2,3)&"."&MID(I2,5,3)&"/"&MID(I2,8,4)&"-"&MID(I2,12,2)),IF(X2="CNPJ_INCOMPLETO_2",("00."&LEFT(I2,3)&"."&MID(I2,4,3)&"/"&MID(I2,7,4)&"-"&MID(I2,11,2)),IF(X2="CNPJ",(LEFT(I2,2)&"."&MID(I2,3,3)&"."&MID(I2,6,3)&"/"&MID(I2,9,4)&"-"&MID(I2,13,2)),IF(X2="CPF_Incompleto",("0"&LEFT(I2,2)&"."&MID(I2,3,3)&"."&MID(I2,6,3)&"-"&MID(I2,9,2)),(LEFT(I2,3)&"."&MID(I2,4,3)&"."&MID(I2,7,3)&"-"&MID(I2,10,2)))))) -> 17.250.059/0001-30 | Z2: =VLOOKUP(Y2,FORNECEDORES!$A$2:$G$9043,3,0) -> SILVERIO DA SILVEIRA ME | AA2: =VLOOKUP(Y2,FORNECEDORES!$A$2:$G$9041,7,0) -> silveriosilveira86@hotmail.com;
A3: CON:277 | B3: 4417812014686304 | C3: 45833 | D3: 45834 | E3: SDO | F3: 200 | G3: EFETIVADA | H3: SILVERIO DA SILVEIRA | I3: 17250059000130 | J3: ATL5J69 | K3: 100902598 | L3: SP | M3: 144264 | N3: 262876 | O3: 277 | P3: RS | Q3: RS | R3: Finalizado | S3: Finalizada | T3: EFETIVADA | U3: Quinta feira | V3: Quinta feira | W3: =LEN(I3) -> 14 | X3: =IF(W3=14,"CNPJ",IF(W3=12,"CNPJ_INCOMPLETO_2",IF(W3=13,"CNPJ_INCOMPLETO_1",IF(W3=10,"CPF_Incompleto","CPF")))) -> CNPJ | Y3: =IF(X3="CNPJ_INCOMPLETO_1",("0"&LEFT(I3,1)&"."&MID(I3,2,3)&"."&MID(I3,5,3)&"/"&MID(I3,8,4)&"-"&MID(I3,12,2)),IF(X3="CNPJ_INCOMPLETO_2",("00."&LEFT(I3,3)&"."&MID(I3,4,3)&"/"&MID(I3,7,4)&"-"&MID(I3,11,2)),IF(X3="CNPJ",(LEFT(I3,2)&"."&MID(I3,3,3)&"."&MID(I3,6,3)&"/"&MID(I3,9,4)&"-"&MID(I3,13,2)),IF(X3="CPF_Incompleto",("0"&LEFT(I3,2)&"."&MID(I3,3,3)&"."&MID(I3,6,3)&"-"&MID(I3,9,2)),(LEFT(I3,3)&"."&MID(I3,4,3)&"."&MID(I3,7,3)&"-"&MID(I3,10,2)))))) -> 17.250.059/0001-30 | Z3: =VLOOKUP(Y3,FORNECEDORES!$A$2:$G$9043,3,0) -> SILVERIO DA SILVEIRA ME | AA3: =VLOOKUP(Y3,FORNECEDORES!$A$2:$G$9041,7,0) -> silveriosilveira86@hotmail.com;
A4: CON:3464 | B4: 4417812010875943 | C4: 45833 | D4: 45863 | E4: DES | F4: 540 | G4: EFETIVADA | H4: ANDRE L.A. ENDRES - ME | I4: 92309194000120 | J4: AFK2804 | K4: 100904258 | L4: SP | M4: 144268 | N4: 262898 | O4: 3464 | P4: RS | Q4: RS | R4: Finalizado | S4: Finalizada | T4: EFETIVADA | U4: 30 | V4: 45868 | W4: =LEN(I4) -> 14 | X4: =IF(W4=14,"CNPJ",IF(W4=12,"CNPJ_INCOMPLETO_2",IF(W4=13,"CNPJ_INCOMPLETO_1",IF(W4=10,"CPF_Incompleto","CPF")))) -> CNPJ | Y4: =IF(X4="CNPJ_INCOMPLETO_1",("0"&LEFT(I4,1)&"."&MID(I4,2,3)&"."&MID(I4,5,3)&"/"&MID(I4,8,4)&"-"&MID(I4,12,2)),IF(X4="CNPJ_INCOMPLETO_2",("00."&LEFT(I4,3)&"."&MID(I4,4,3)&"/"&MID(I4,7,4)&"-"&MID(I4,11,2)),IF(X4="CNPJ",(LEFT(I4,2)&"."&MID(I4,3,3)&"."&MID(I4,6,3)&"/"&MID(I4,9,4)&"-"&MID(I4,13,2)),IF(X4="CPF_Incompleto",("0"&LEFT(I4,2)&"."&MID(I4,3,3)&"."&MID(I4,6,3)&"-"&MID(I4,9,2)),(LEFT(I4,3)&"."&MID(I4,4,3)&"."&MID(I4,7,3)&"-"&MID(I4,10,2)))))) -> 92.309.194/0001-20 | Z4: =VLOOKUP(Y4,FORNECEDORES!$A$2:$G$9043,3,0) -> ANDRE L.A. ENDRES - ME | AA4: =VLOOKUP(Y4,FORNECEDORES!$A$2:$G$9041,7,0) -> endrestransportes@outlook.com
A5: CON:3466 | B5: 4417812013265605 | C5: 45833 | D5: 45834 | E5: ADT | F5: 1693.02 | G5: EFETIVADA | H5: VANDERLI DASSOLER | I5: 58751050030 | J5: MKS4A50 | K5: 100923624 | L5: SP | M5: 144295 | N5: 262986 | O5: 3466 | P5: RS | Q5: RS | R5: Finalizado | S5: Finalizada | T5: EFETIVADA | U5: Quinta feira | V5: Quinta feira | W5: =LEN(I5) -> 11 | X5: =IF(W5=14,"CNPJ",IF(W5=12,"CNPJ_INCOMPLETO_2",IF(W5=13,"CNPJ_INCOMPLETO_1",IF(W5=10,"CPF_Incompleto","CPF")))) -> CPF | Y5: =IF(X5="CNPJ_INCOMPLETO_1",("0"&LEFT(I5,1)&"."&MID(I5,2,3)&"."&MID(I5,5,3)&"/"&MID(I5,8,4)&"-"&MID(I5,12,2)),IF(X5="CNPJ_INCOMPLETO_2",("00."&LEFT(I5,3)&"."&MID(I5,4,3)&"/"&MID(I5,7,4)&"-"&MID(I5,11,2)),IF(X5="CNPJ",(LEFT(I5,2)&"."&MID(I5,3,3)&"."&MID(I5,6,3)&"/"&MID(I5,9,4)&"-"&MID(I5,13,2)),IF(X5="CPF_Incompleto",("0"&LEFT(I5,2)&"."&MID(I5,3,3)&"."&MID(I5,6,3)&"-"&MID(I5,9,2)),(LEFT(I5,3)&"."&MID(I5,4,3)&"."&MID(I5,7,3)&"-"&MID(I5,10,2)))))) -> 587.510.500-30 | Z5: =VLOOKUP(Y5,FORNECEDORES!$A$2:$G$9043,3,0) -> VANDERLI DASSOLER | AA5: =VLOOKUP(Y5,FORNECEDORES!$A$2:$G$9041,7,0) -> vanderliegv@gmail.com;
A6: CON:3466 | B6: 4417812013265605 | C6: 45833 | D6: 45834 | E6: SDO | F6: 1128.68 | G6: EFETIVADA | H6: VANDERLI DASSOLER | I6: 58751050030 | J6: MKS4A50 | K6: 100923624 | L6: SP | M6: 144295 | N6: 262986 | O6: 3466 | P6: RS | Q6: RS | R6: Finalizado | S6: Finalizada | T6: EFETIVADA | U6: Quinta feira | V6: Quinta feira | W6: =LEN(I6) -> 11 | X6: =IF(W6=14,"CNPJ",IF(W6=12,"CNPJ_INCOMPLETO_2",IF(W6=13,"CNPJ_INCOMPLETO_1",IF(W6=10,"CPF_Incompleto","CPF")))) -> CPF | Y6: =IF(X6="CNPJ_INCOMPLETO_1",("0"&LEFT(I6,1)&"."&MID(I6,2,3)&"."&MID(I6,5,3)&"/"&MID(I6,8,4)&"-"&MID(I6,12,2)),IF(X6="CNPJ_INCOMPLETO_2",("00."&LEFT(I6,3)&"."&MID(I6,4,3)&"/"&MID(I6,7,4)&"-"&MID(I6,11,2)),IF(X6="CNPJ",(LEFT(I6,2)&"."&MID(I6,3,3)&"."&MID(I6,6,3)&"/"&MID(I6,9,4)&"-"&MID(I6,13,2)),IF(X6="CPF_Incompleto",("0"&LEFT(I6,2)&"."&MID(I6,3,3)&"."&MID(I6,6,3)&"-"&MID(I6,9,2)),(LEFT(I6,3)&"."&MID(I6,4,3)&"."&MID(I6,7,3)&"-"&MID(I6,10,2)))))) -> 587.510.500-30 | Z6: =VLOOKUP(Y6,FORNECEDORES!$A$2:$G$9043,3,0) -> VANDERLI DASSOLER | AA6: =VLOOKUP(Y6,FORNECEDORES!$A$2:$G$9041,7,0) -> vanderliegv@gmail.com;
A7: CON:3467 | B7: 4417812010875943 | C7: 45833 | D7: 45863 | E7: DES | F7: 2700 | G7: EFETIVADA | H7: ANDRE L.A. ENDRES - ME | I7: 92309194000120 | J7: AFK2804 | K7: 100928877 | L7: SP | M7: 144301 | N7: 262997 | O7: 3467 | P7: RS | Q7: RS | R7: Finalizado | S7: Finalizada | T7: EFETIVADA | U7: 30 | V7: 45868 | W7: =LEN(I7) -> 14 | X7: =IF(W7=14,"CNPJ",IF(W7=12,"CNPJ_INCOMPLETO_2",IF(W7=13,"CNPJ_INCOMPLETO_1",IF(W7=10,"CPF_Incompleto","CPF")))) -> CNPJ | Y7: =IF(X7="CNPJ_INCOMPLETO_1",("0"&LEFT(I7,1)&"."&MID(I7,2,3)&"."&MID(I7,5,3)&"/"&MID(I7,8,4)&"-"&MID(I7,12,2)),IF(X7="CNPJ_INCOMPLETO_2",("00."&LEFT(I7,3)&"."&MID(I7,4,3)&"/"&MID(I7,7,4)&"-"&MID(I7,11,2)),IF(X7="CNPJ",(LEFT(I7,2)&"."&MID(I7,3,3)&"."&MID(I7,6,3)&"/"&MID(I7,9,4)&"-"&MID(I7,13,2)),IF(X7="CPF_Incompleto",("0"&LEFT(I7,2)&"."&MID(I7,3,3)&"."&MID(I7,6,3)&"-"&MID(I7,9,2)),(LEFT(I7,3)&"."&MID(I7,4,3)&"."&MID(I7,7,3)&"-"&MID(I7,10,2)))))) -> 92.309.194/0001-20 | Z7: =VLOOKUP(Y7,FORNECEDORES!$A$2:$G$9043,3,0) -> ANDRE L.A. ENDRES - ME | AA7: =VLOOKUP(Y7,FORNECEDORES!$A$2:$G$9041,7,0) -> endrestransportes@outlook.com
A8: CON:3468 | B8: 4417812015511030 | C8: 45834 | D8: 45834 | E8: ADT | F8: 992.46 | G8: EFETIVADA | H8: Denis Camillo Da Silva | I8: 96685697091 | J8: IQM9933 | K8: 100946382 | L8: SP | M8: 144327 | N8: 263038 | O8: 3468, 3469 | P8: RS | Q8: RS | R8: Finalizado | S8: Finalizada | T8: EFETIVADA | U8: Quinta feira | V8: Quinta feira | W8: =LEN(I8) -> 11 | X8: =IF(W8=14,"CNPJ",IF(W8=12,"CNPJ_INCOMPLETO_2",IF(W8=13,"CNPJ_INCOMPLETO_1",IF(W8=10,"CPF_Incompleto","CPF")))) -> CPF | Y8: =IF(X8="CNPJ_INCOMPLETO_1",("0"&LEFT(I8,1)&"."&MID(I8,2,3)&"."&MID(I8,5,3)&"/"&MID(I8,8,4)&"-"&MID(I8,12,2)),IF(X8="CNPJ_INCOMPLETO_2",("00."&LEFT(I8,3)&"."&MID(I8,4,3)&"/"&MID(I8,7,4)&"-"&MID(I8,11,2)),IF(X8="CNPJ",(LEFT(I8,2)&"."&MID(I8,3,3)&"."&MID(I8,6,3)&"/"&MID(I8,9,4)&"-"&MID(I8,13,2)),IF(X8="CPF_Incompleto",("0"&LEFT(I8,2)&"."&MID(I8,3,3)&"."&MID(I8,6,3)&"-"&MID(I8,9,2)),(LEFT(I8,3)&"."&MID(I8,4,3)&"."&MID(I8,7,3)&"-"&MID(I8,10,2)))))) -> 966.856.970-91 | Z8: =VLOOKUP(Y8,FORNECEDORES!$A$2:$G$9043,3,0) -> DENIS CAMILLO DA SILVA | AA8: =VLOOKUP(Y8,FORNECEDORES!$A$2:$G$9041,7,0) -> deniscamillo29@gmail.com;
A9: CON:3468 | B9: 4417812015511030 | C9: 45834 | D9: 45841 | E9: SDO | F9: 661.64 | G9: EFETIVADA | H9: Denis Camillo Da Silva | I9: 96685697091 | J9: IQM9933 | K9: 100946382 | L9: SP | M9: 144327 | N9: 263038 | O9: 3468, 3469 | P9: RS | Q9: RS | R9: Finalizado | S9: Finalizada | T9: EFETIVADA | U9: Quinta feira | V9: Quinta feira | W9: =LEN(I9) -> 11 | X9: =IF(W9=14,"CNPJ",IF(W9=12,"CNPJ_INCOMPLETO_2",IF(W9=13,"CNPJ_INCOMPLETO_1",IF(W9=10,"CPF_Incompleto","CPF")))) -> CPF | Y9: =IF(X9="CNPJ_INCOMPLETO_1",("0"&LEFT(I9,1)&"."&MID(I9,2,3)&"."&MID(I9,5,3)&"/"&MID(I9,8,4)&"-"&MID(I9,12,2)),IF(X9="CNPJ_INCOMPLETO_2",("00."&LEFT(I9,3)&"."&MID(I9,4,3)&"/"&MID(I9,7,4)&"-"&MID(I9,11,2)),IF(X9="CNPJ",(LEFT(I9,2)&"."&MID(I9,3,3)&"."&MID(I9,6,3)&"/"&MID(I9,9,4)&"-"&MID(I9,13,2)),IF(X9="CPF_Incompleto",("0"&LEFT(I9,2)&"."&MID(I9,3,3)&"."&MID(I9,6,3)&"-"&MID(I9,9,2)),(LEFT(I9,3)&"."&MID(I9,4,3)&"."&MID(I9,7,3)&"-"&MID(I9,10,2)))))) -> 966.856.970-91 | Z9: =VLOOKUP(Y9,FORNECEDORES!$A$2:$G$9043,3,0) -> DENIS CAMILLO DA SILVA | AA9: =VLOOKUP(Y9,FORNECEDORES!$A$2:$G$9041,7,0) -> deniscamillo29@gmail.com;
A10: CON:3470 | B10: 4417812022858440 | C10: 45834 | D10: 45834 | E10: ADT | F10: 1693.02 | G10: EFETIVADA | H10: JOSE DAGOBERTO MACHADO | I10: 40573680000 | J10: IKV8F25 | K10: 100951395 | L10: SP | M10: 144330 | N10: 263046 | O10: 3470 | P10: RS | Q10: RS | R10: Finalizado | S10: Finalizada | T10: EFETIVADA | U10: Quinta feira | V10: Quinta feira | W10: =LEN(I10) -> 11 | X10: =IF(W10=14,"CNPJ",IF(W10=12,"CNPJ_INCOMPLETO_2",IF(W10=13,"CNPJ_INCOMPLETO_1",IF(W10=10,"CPF_Incompleto","CPF")))) -> CPF | Y10: =IF(X10="CNPJ_INCOMPLETO_1",("0"&LEFT(I10,1)&"."&MID(I10,2,3)&"."&MID(I10,5,3)&"/"&MID(I10,8,4)&"-"&MID(I10,12,2)),IF(X10="CNPJ_INCOMPLETO_2",("00."&LEFT(I10,3)&"."&MID(I10,4,3)&"/"&MID(I10,7,4)&"-"&MID(I10,11,2)),IF(X10="CNPJ",(LEFT(I10,2)&"."&MID(I10,3,3)&"."&MID(I10,6,3)&"/"&MID(I10,9,4)&"-"&MID(I10,13,2)),IF(X10="CPF_Incompleto",("0"&LEFT(I10,2)&"."&MID(I10,3,3)&"."&MID(I10,6,3)&"-"&MID(I10,9,2)),(LEFT(I10,3)&"."&MID(I10,4,3)&"."&MID(I10,7,3)&"-"&MID(I10,10,2)))))) -> 405.736.800-00 | Z10: =VLOOKUP(Y10,FORNECEDORES!$A$2:$G$9043,3,0) -> JOSÉ DAGOBERTO MACHADO | AA10: =VLOOKUP(Y10,FORNECEDORES!$A$2:$G$9041,7,0) -> jdmdago@gmail.com;
A11: CON:3470 | B11: 4417812022858440 | C11: 45834 | D11: 45841 | E11: SDO | F11: 1128.68 | G11: EFETIVADA | H11: JOSE DAGOBERTO MACHADO | I11: 40573680000 | J11: IKV8F25 | K11: 100951395 | L11: SP | M11: 144330 | N11: 263046 | O11: 3470 | P11: RS | Q11: RS | R11: Finalizado | S11: Finalizada | T11: EFETIVADA | U11: Quinta feira | V11: Quinta feira | W11: =LEN(I11) -> 11 | X11: =IF(W11=14,"CNPJ",IF(W11=12,"CNPJ_INCOMPLETO_2",IF(W11=13,"CNPJ_INCOMPLETO_1",IF(W11=10,"CPF_Incompleto","CPF")))) -> CPF | Y11: =IF(X11="CNPJ_INCOMPLETO_1",("0"&LEFT(I11,1)&"."&MID(I11,2,3)&"."&MID(I11,5,3)&"/"&MID(I11,8,4)&"-"&MID(I11,12,2)),IF(X11="CNPJ_INCOMPLETO_2",("00."&LEFT(I11,3)&"."&MID(I11,4,3)&"/"&MID(I11,7,4)&"-"&MID(I11,11,2)),IF(X11="CNPJ",(LEFT(I11,2)&"."&MID(I11,3,3)&"."&MID(I11,6,3)&"/"&MID(I11,9,4)&"-"&MID(I11,13,2)),IF(X11="CPF_Incompleto",("0"&LEFT(I11,2)&"."&MID(I11,3,3)&"."&MID(I11,6,3)&"-"&MID(I11,9,2)),(LEFT(I11,3)&"."&MID(I11,4,3)&"."&MID(I11,7,3)&"-"&MID(I11,10,2)))))) -> 405.736.800-00 | Z11: =VLOOKUP(Y11,FORNECEDORES!$A$2:$G$9043,3,0) -> JOSÉ DAGOBERTO MACHADO | AA11: =VLOOKUP(Y11,FORNECEDORES!$A$2:$G$9041,7,0) -> jdmdago@gmail.com;
A12: CON:3472 | B12: 4417812013265605 | C12: 45835 | D12: 45835 | E12: ADT | F12: 1576.26 | G12: EFETIVADA | H12: VANDERLI DASSOLER | I12: 58751050030 | J12: MKS4A50 | K12: 100980043 | L12: SP | M12: 144379 | N12: 263152 | O12: 3472 | P12: RS | Q12: RS | R12: Finalizado | S12: Finalizada | T12: EFETIVADA | U12: Quinta feira | V12: Quinta feira | W12: =LEN(I12) -> 11 | X12: =IF(W12=14,"CNPJ",IF(W12=12,"CNPJ_INCOMPLETO_2",IF(W12=13,"CNPJ_INCOMPLETO_1",IF(W12=10,"CPF_Incompleto","CPF")))) -> CPF | Y12: =IF(X12="CNPJ_INCOMPLETO_1",("0"&LEFT(I12,1)&"."&MID(I12,2,3)&"."&MID(I12,5,3)&"/"&MID(I12,8,4)&"-"&MID(I12,12,2)),IF(X12="CNPJ_INCOMPLETO_2",("00."&LEFT(I12,3)&"."&MID(I12,4,3)&"/"&MID(I12,7,4)&"-"&MID(I12,11,2)),IF(X12="CNPJ",(LEFT(I12,2)&"."&MID(I12,3,3)&"."&MID(I12,6,3)&"/"&MID(I12,9,4)&"-"&MID(I12,13,2)),IF(X12="CPF_Incompleto",("0"&LEFT(I12,2)&"."&MID(I12,3,3)&"."&MID(I12,6,3)&"-"&MID(I12,9,2)),(LEFT(I12,3)&"."&MID(I12,4,3)&"."&MID(I12,7,3)&"-"&MID(I12,10,2)))))) -> 587.510.500-30 | Z12: =VLOOKUP(Y12,FORNECEDORES!$A$2:$G$9043,3,0) -> VANDERLI DASSOLER | AA12: =VLOOKUP(Y12,FORNECEDORES!$A$2:$G$9041,7,0) -> vanderliegv@gmail.com;
A13: CON:3472 | B13: 4417812013265605 | C13: 45835 | D13: 45841 | E13: SDO | F13: 1050.84 | G13: EFETIVADA | H13: VANDERLI DASSOLER | I13: 58751050030 | J13: MKS4A50 | K13: 100980043 | L13: SP | M13: 144379 | N13: 263152 | O13: 3472 | P13: RS | Q13: RS | R13: Finalizado | S13: Finalizada | T13: EFETIVADA | U13: Quinta feira | V13: Quinta feira | W13: =LEN(I13) -> 11 | X13: =IF(W13=14,"CNPJ",IF(W13=12,"CNPJ_INCOMPLETO_2",IF(W13=13,"CNPJ_INCOMPLETO_1",IF(W13=10,"CPF_Incompleto","CPF")))) -> CPF | Y13: =IF(X13="CNPJ_INCOMPLETO_1",("0"&LEFT(I13,1)&"."&MID(I13,2,3)&"."&MID(I13,5,3)&"/"&MID(I13,8,4)&"-"&MID(I13,12,2)),IF(X13="CNPJ_INCOMPLETO_2",("00."&LEFT(I13,3)&"."&MID(I13,4,3)&"/"&MID(I13,7,4)&"-"&MID(I13,11,2)),IF(X13="CNPJ",(LEFT(I13,2)&"."&MID(I13,3,3)&"."&MID(I13,6,3)&"/"&MID(I13,9,4)&"-"&MID(I13,13,2)),IF(X13="CPF_Incompleto",("0"&LEFT(I13,2)&"."&MID(I13,3,3)&"."&MID(I13,6,3)&"-"&MID(I13,9,2)),(LEFT(I13,3)&"."&MID(I13,4,3)&"."&MID(I13,7,3)&"-"&MID(I13,10,2)))))) -> 587.510.500-30 | Z13: =VLOOKUP(Y13,FORNECEDORES!$A$2:$G$9043,3,0) -> VANDERLI DASSOLER | AA13: =VLOOKUP(Y13,FORNECEDORES!$A$2:$G$9041,7,0) -> vanderliegv@gmail.com;
A14: CON:3473 | B14: 4417812010875943 | C14: 45835 | D14: 45866 | E14: DES | F14: 1800 | G14: EFETIVADA | H14: ANDRE L.A. ENDRES - ME | I14: 92309194000120 | J14: AFK2804 | K14: 100981423 | L14: SP | M14: 144380 | N14: 263153 | O14: 3473 | P14: RS | Q14: RS | R14: Finalizado | S14: Finalizada | T14: EFETIVADA | U14: 30 | V14: 45868 | W14: =LEN(I14) -> 14 | X14: =IF(W14=14,"CNPJ",IF(W14=12,"CNPJ_INCOMPLETO_2",IF(W14=13,"CNPJ_INCOMPLETO_1",IF(W14=10,"CPF_Incompleto","CPF")))) -> CNPJ | Y14: =IF(X14="CNPJ_INCOMPLETO_1",("0"&LEFT(I14,1)&"."&MID(I14,2,3)&"."&MID(I14,5,3)&"/"&MID(I14,8,4)&"-"&MID(I14,12,2)),IF(X14="CNPJ_INCOMPLETO_2",("00."&LEFT(I14,3)&"."&MID(I14,4,3)&"/"&MID(I14,7,4)&"-"&MID(I14,11,2)),IF(X14="CNPJ",(LEFT(I14,2)&"."&MID(I14,3,3)&"."&MID(I14,6,3)&"/"&MID(I14,9,4)&"-"&MID(I14,13,2)),IF(X14="CPF_Incompleto",("0"&LEFT(I14,2)&"."&MID(I14,3,3)&"."&MID(I14,6,3)&"-"&MID(I14,9,2)),(LEFT(I14,3)&"."&MID(I14,4,3)&"."&MID(I14,7,3)&"-"&MID(I14,10,2)))))) -> 92.309.194/0001-20 | Z14: =VLOOKUP(Y14,FORNECEDORES!$A$2:$G$9043,3,0) -> ANDRE L.A. ENDRES - ME | AA14: =VLOOKUP(Y14,FORNECEDORES!$A$2:$G$9041,7,0) -> endrestransportes@outlook.com
A15: CON:3475 | B15: 4417812013265605 | C15: 45838 | D15: 45839 | E15: ADT | F15: 1693.02 | G15: EFETIVADA | H15: VANDERLI DASSOLER | I15: 58751050030 | J15: MKS4A50 | K15: 101072217 | L15: SP | M15: 144516 | N15: 263407 | O15: 3475 | P15: RS | Q15: RS | R15: Finalizado | S15: Finalizada | T15: EFETIVADA | U15: Quinta feira | V15: Quinta feira | W15: =LEN(I15) -> 11 | X15: =IF(W15=14,"CNPJ",IF(W15=12,"CNPJ_INCOMPLETO_2",IF(W15=13,"CNPJ_INCOMPLETO_1",IF(W15=10,"CPF_Incompleto","CPF")))) -> CPF | Y15: =IF(X15="CNPJ_INCOMPLETO_1",("0"&LEFT(I15,1)&"."&MID(I15,2,3)&"."&MID(I15,5,3)&"/"&MID(I15,8,4)&"-"&MID(I15,12,2)),IF(X15="CNPJ_INCOMPLETO_2",("00."&LEFT(I15,3)&"."&MID(I15,4,3)&"/"&MID(I15,7,4)&"-"&MID(I15,11,2)),IF(X15="CNPJ",(LEFT(I15,2)&"."&MID(I15,3,3)&"."&MID(I15,6,3)&"/"&MID(I15,9,4)&"-"&MID(I15,13,2)),IF(X15="CPF_Incompleto",("0"&LEFT(I15,2)&"."&MID(I15,3,3)&"."&MID(I15,6,3)&"-"&MID(I15,9,2)),(LEFT(I15,3)&"."&MID(I15,4,3)&"."&MID(I15,7,3)&"-"&MID(I15,10,2)))))) -> 587.510.500-30 | Z15: =VLOOKUP(Y15,FORNECEDORES!$A$2:$G$9043,3,0) -> VANDERLI DASSOLER | AA15: =VLOOKUP(Y15,FORNECEDORES!$A$2:$G$9041,7,0) -> vanderliegv@gmail.com;
A16: CON:3475 | B16: 4417812013265605 | C16: 45838 | D16: 45841 | E16: SDO | F16: 1128.68 | G16: EFETIVADA | H16: VANDERLI DASSOLER | I16: 58751050030 | J16: MKS4A50 | K16: 101072217 | L16: SP | M16: 144516 | N16: 263407 | O16: 3475 | P16: RS | Q16: RS | R16: Finalizado | S16: Finalizada | T16: EFETIVADA | U16: Quinta feira | V16: Quinta feira | W16: =LEN(I16) -> 11 | X16: =IF(W16=14,"CNPJ",IF(W16=12,"CNPJ_INCOMPLETO_2",IF(W16=13,"CNPJ_INCOMPLETO_1",IF(W16=10,"CPF_Incompleto","CPF")))) -> CPF | Y16: =IF(X16="CNPJ_INCOMPLETO_1",("0"&LEFT(I16,1)&"."&MID(I16,2,3)&"."&MID(I16,5,3)&"/"&MID(I16,8,4)&"-"&MID(I16,12,2)),IF(X16="CNPJ_INCOMPLETO_2",("00."&LEFT(I16,3)&"."&MID(I16,4,3)&"/"&MID(I16,7,4)&"-"&MID(I16,11,2)),IF(X16="CNPJ",(LEFT(I16,2)&"."&MID(I16,3,3)&"."&MID(I16,6,3)&"/"&MID(I16,9,4)&"-"&MID(I16,13,2)),IF(X16="CPF_Incompleto",("0"&LEFT(I16,2)&"."&MID(I16,3,3)&"."&MID(I16,6,3)&"-"&MID(I16,9,2)),(LEFT(I16,3)&"."&MID(I16,4,3)&"."&MID(I16,7,3)&"-"&MID(I16,10,2)))))) -> 587.510.500-30 | Z16: =VLOOKUP(Y16,FORNECEDORES!$A$2:$G$9043,3,0) -> VANDERLI DASSOLER | AA16: =VLOOKUP(Y16,FORNECEDORES!$A$2:$G$9041,7,0) -> vanderliegv@gmail.com;
A17: CON:3476 | B17: 4417812010875943 | C17: 45838 | D17: 45868 | E17: DES | F17: 1800 | G17: EFETIVADA | H17: ANDRE L.A. ENDRES - ME | I17: 92309194000120 | J17: AFK2804 | K17: 101072261 | L17: SP | M17: 144517 | N17: 263408 | O17: 3476 | P17: RS | Q17: RS | R17: Finalizado | S17: Finalizada | T17: EFETIVADA | U17: 30 | V17: 45868 | W17: =LEN(I17) -> 14 | X17: =IF(W17=14,"CNPJ",IF(W17=12,"CNPJ_INCOMPLETO_2",IF(W17=13,"CNPJ_INCOMPLETO_1",IF(W17=10,"CPF_Incompleto","CPF")))) -> CNPJ | Y17: =IF(X17="CNPJ_INCOMPLETO_1",("0"&LEFT(I17,1)&"."&MID(I17,2,3)&"."&MID(I17,5,3)&"/"&MID(I17,8,4)&"-"&MID(I17,12,2)),IF(X17="CNPJ_INCOMPLETO_2",("00."&LEFT(I17,3)&"."&MID(I17,4,3)&"/"&MID(I17,7,4)&"-"&MID(I17,11,2)),IF(X17="CNPJ",(LEFT(I17,2)&"."&MID(I17,3,3)&"."&MID(I17,6,3)&"/"&MID(I17,9,4)&"-"&MID(I17,13,2)),IF(X17="CPF_Incompleto",("0"&LEFT(I17,2)&"."&MID(I17,3,3)&"."&MID(I17,6,3)&"-"&MID(I17,9,2)),(LEFT(I17,3)&"."&MID(I17,4,3)&"."&MID(I17,7,3)&"-"&MID(I17,10,2)))))) -> 92.309.194/0001-20 | Z17: =VLOOKUP(Y17,FORNECEDORES!$A$2:$G$9043,3,0) -> ANDRE L.A. ENDRES - ME | AA17: =VLOOKUP(Y17,FORNECEDORES!$A$2:$G$9041,7,0) -> endrestransportes@outlook.com
A18: CON:3477 | B18: 4417812014686304 | C18: 45838 | D18: 45839 | E18: ADT | F18: 1740 | G18: EFETIVADA | H18: SILVERIO DA SILVEIRA | I18: 17250059000130 | J18: ATL5J69 | K18: 101080661 | L18: SP | M18: 144520 | N18: 263428 | O18: 3477 | P18: RS | Q18: RS | R18: Finalizado | S18: Finalizada | T18: EFETIVADA | U18: Quinta feira | V18: Quinta feira | W18: =LEN(I18) -> 14 | X18: =IF(W18=14,"CNPJ",IF(W18=12,"CNPJ_INCOMPLETO_2",IF(W18=13,"CNPJ_INCOMPLETO_1",IF(W18=10,"CPF_Incompleto","CPF")))) -> CNPJ | Y18: =IF(X18="CNPJ_INCOMPLETO_1",("0"&LEFT(I18,1)&"."&MID(I18,2,3)&"."&MID(I18,5,3)&"/"&MID(I18,8,4)&"-"&MID(I18,12,2)),IF(X18="CNPJ_INCOMPLETO_2",("00."&LEFT(I18,3)&"."&MID(I18,4,3)&"/"&MID(I18,7,4)&"-"&MID(I18,11,2)),IF(X18="CNPJ",(LEFT(I18,2)&"."&MID(I18,3,3)&"."&MID(I18,6,3)&"/"&MID(I18,9,4)&"-"&MID(I18,13,2)),IF(X18="CPF_Incompleto",("0"&LEFT(I18,2)&"."&MID(I18,3,3)&"."&MID(I18,6,3)&"-"&MID(I18,9,2)),(LEFT(I18,3)&"."&MID(I18,4,3)&"."&MID(I18,7,3)&"-"&MID(I18,10,2)))))) -> 17.250.059/0001-30 | Z18: =VLOOKUP(Y18,FORNECEDORES!$A$2:$G$9043,3,0) -> SILVERIO DA SILVEIRA ME | AA18: =VLOOKUP(Y18,FORNECEDORES!$A$2:$G$9041,7,0) -> silveriosilveira86@hotmail.com;
A19: CON:3477 | B19: 4417812014686304 | C19: 45838 | D19: 45841 | E19: SDO | F19: 1160 | G19: EFETIVADA | H19: SILVERIO DA SILVEIRA | I19: 17250059000130 | J19: ATL5J69 | K19: 101080661 | L19: SP | M19: 144520 | N19: 263428 | O19: 3477 | P19: RS | Q19: RS | R19: Finalizado | S19: Finalizada | T19: EFETIVADA | U19: Quinta feira | V19: Quinta feira | W19: =LEN(I19) -> 14 | X19: =IF(W19=14,"CNPJ",IF(W19=12,"CNPJ_INCOMPLETO_2",IF(W19=13,"CNPJ_INCOMPLETO_1",IF(W19=10,"CPF_Incompleto","CPF")))) -> CNPJ | Y19: =IF(X19="CNPJ_INCOMPLETO_1",("0"&LEFT(I19,1)&"."&MID(I19,2,3)&"."&MID(I19,5,3)&"/"&MID(I19,8,4)&"-"&MID(I19,12,2)),IF(X19="CNPJ_INCOMPLETO_2",("00."&LEFT(I19,3)&"."&MID(I19,4,3)&"/"&MID(I19,7,4)&"-"&MID(I19,11,2)),IF(X19="CNPJ",(LEFT(I19,2)&"."&MID(I19,3,3)&"."&MID(I19,6,3)&"/"&MID(I19,9,4)&"-"&MID(I19,13,2)),IF(X19="CPF_Incompleto",("0"&LEFT(I19,2)&"."&MID(I19,3,3)&"."&MID(I19,6,3)&"-"&MID(I19,9,2)),(LEFT(I19,3)&"."&MID(I19,4,3)&"."&MID(I19,7,3)&"-"&MID(I19,10,2)))))) -> 17.250.059/0001-30 | Z19: =VLOOKUP(Y19,FORNECEDORES!$A$2:$G$9043,3,0) -> SILVERIO DA SILVEIRA ME | AA19: =VLOOKUP(Y19,FORNECEDORES!$A$2:$G$9041,7,0) -> silveriosilveira86@hotmail.com;
A20: CON:3478 | B20: 4417812022858440 | C20: 45838 | D20: 45839 | E20: ADT | F20: 1576.26 | G20: EFETIVADA | H20: JOSE DAGOBERTO MACHADO | I20: 40573680000 | J20: IKV8F25 | K20: 101081771 | L20: SP | M20: 144523 | N20: 263434 | O20: 3478 | P20: RS | Q20: RS | R20: Finalizado | S20: Finalizada | T20: EFETIVADA | U20: Quinta feira | V20: Quinta feira | W20: =LEN(I20) -> 11 | X20: =IF(W20=14,"CNPJ",IF(W20=12,"CNPJ_INCOMPLETO_2",IF(W20=13,"CNPJ_INCOMPLETO_1",IF(W20=10,"CPF_Incompleto","CPF")))) -> CPF | Y20: =IF(X20="CNPJ_INCOMPLETO_1",("0"&LEFT(I20,1)&"."&MID(I20,2,3)&"."&MID(I20,5,3)&"/"&MID(I20,8,4)&"-"&MID(I20,12,2)),IF(X20="CNPJ_INCOMPLETO_2",("00."&LEFT(I20,3)&"."&MID(I20,4,3)&"/"&MID(I20,7,4)&"-"&MID(I20,11,2)),IF(X20="CNPJ",(LEFT(I20,2)&"."&MID(I20,3,3)&"."&MID(I20,6,3)&"/"&MID(I20,9,4)&"-"&MID(I20,13,2)),IF(X20="CPF_Incompleto",("0"&LEFT(I20,2)&"."&MID(I20,3,3)&"."&MID(I20,6,3)&"-"&MID(I20,9,2)),(LEFT(I20,3)&"."&MID(I20,4,3)&"."&MID(I20,7,3)&"-"&MID(I20,10,2)))))) -> 405.736.800-00 | Z20: =VLOOKUP(Y20,FORNECEDORES!$A$2:$G$9043,3,0) -> JOSÉ DAGOBERTO MACHADO | AA20: =VLOOKUP(Y20,FORNECEDORES!$A$2:$G$9041,7,0) -> jdmdago@gmail.com;
A21: CON:3478 | B21: 4417812022858440 | C21: 45838 | D21: 45841 | E21: SDO | F21: 1050.84 | G21: EFETIVADA | H21: JOSE DAGOBERTO MACHADO | I21: 40573680000 | J21: IKV8F25 | K21: 101081771 | L21: SP | M21: 144523 | N21: 263434 | O21: 3478 | P21: RS | Q21: RS | R21: Finalizado | S21: Finalizada | T21: EFETIVADA | U21: Quinta feira | V21: Quinta feira | W21: =LEN(I21) -> 11 | X21: =IF(W21=14,"CNPJ",IF(W21=12,"CNPJ_INCOMPLETO_2",IF(W21=13,"CNPJ_INCOMPLETO_1",IF(W21=10,"CPF_Incompleto","CPF")))) -> CPF | Y21: =IF(X21="CNPJ_INCOMPLETO_1",("0"&LEFT(I21,1)&"."&MID(I21,2,3)&"."&MID(I21,5,3)&"/"&MID(I21,8,4)&"-"&MID(I21,12,2)),IF(X21="CNPJ_INCOMPLETO_2",("00."&LEFT(I21,3)&"."&MID(I21,4,3)&"/"&MID(I21,7,4)&"-"&MID(I21,11,2)),IF(X21="CNPJ",(LEFT(I21,2)&"."&MID(I21,3,3)&"."&MID(I21,6,3)&"/"&MID(I21,9,4)&"-"&MID(I21,13,2)),IF(X21="CPF_Incompleto",("0"&LEFT(I21,2)&"."&MID(I21,3,3)&"."&MID(I21,6,3)&"-"&MID(I21,9,2)),(LEFT(I21,3)&"."&MID(I21,4,3)&"."&MID(I21,7,3)&"-"&MID(I21,10,2)))))) -> 405.736.800-00 | Z21: =VLOOKUP(Y21,FORNECEDORES!$A$2:$G$9043,3,0) -> JOSÉ DAGOBERTO MACHADO | AA21: =VLOOKUP(Y21,FORNECEDORES!$A$2:$G$9041,7,0) -> jdmdago@gmail.com;
A22: CON:3479 | B22: 4417812010875943 | C22: 45839 | D22: 45869 | E22: DES | F22: 540 | G22: EFETIVADA | H22: ANDRE L.A. ENDRES - ME | I22: 92309194000120 | J22: AFK2804 | K22: 101098131 | L22: SP | M22: 144544 | N22: 263466 | O22: 3479 | P22: RS | Q22: RS | R22: Finalizado | S22: Finalizada | T22: EFETIVADA | U22: 30 | V22: 45868 | W22: =LEN(I22) -> 14 | X22: =IF(W22=14,"CNPJ",IF(W22=12,"CNPJ_INCOMPLETO_2",IF(W22=13,"CNPJ_INCOMPLETO_1",IF(W22=10,"CPF_Incompleto","CPF")))) -> CNPJ | Y22: =IF(X22="CNPJ_INCOMPLETO_1",("0"&LEFT(I22,1)&"."&MID(I22,2,3)&"."&MID(I22,5,3)&"/"&MID(I22,8,4)&"-"&MID(I22,12,2)),IF(X22="CNPJ_INCOMPLETO_2",("00."&LEFT(I22,3)&"."&MID(I22,4,3)&"/"&MID(I22,7,4)&"-"&MID(I22,11,2)),IF(X22="CNPJ",(LEFT(I22,2)&"."&MID(I22,3,3)&"."&MID(I22,6,3)&"/"&MID(I22,9,4)&"-"&MID(I22,13,2)),IF(X22="CPF_Incompleto",("0"&LEFT(I22,2)&"."&MID(I22,3,3)&"."&MID(I22,6,3)&"-"&MID(I22,9,2)),(LEFT(I22,3)&"."&MID(I22,4,3)&"."&MID(I22,7,3)&"-"&MID(I22,10,2)))))) -> 92.309.194/0001-20 | Z22: =VLOOKUP(Y22,FORNECEDORES!$A$2:$G$9043,3,0) -> ANDRE L.A. ENDRES - ME | AA22: =VLOOKUP(Y22,FORNECEDORES!$A$2:$G$9041,7,0) -> endrestransportes@outlook.com
A23: CON:3481 | B23: 4417812015511030 | C23: 45839 | D23: 45839 | E23: ADT | F23: 992.46 | G23: EFETIVADA | H23: Denis Camillo Da Silva | I23: 96685697091 | J23: IQM9933 | K23: 101106138 | L23: SP | M23: 144558 | N23: 263557 | O23: 3481, 3482, 3483 | P23: RS | Q23: RS | R23: Finalizado | S23: Finalizada | T23: EFETIVADA | U23: Quinta feira | V23: Quinta feira | W23: =LEN(I23) -> 11 | X23: =IF(W23=14,"CNPJ",IF(W23=12,"CNPJ_INCOMPLETO_2",IF(W23=13,"CNPJ_INCOMPLETO_1",IF(W23=10,"CPF_Incompleto","CPF")))) -> CPF | Y23: =IF(X23="CNPJ_INCOMPLETO_1",("0"&LEFT(I23,1)&"."&MID(I23,2,3)&"."&MID(I23,5,3)&"/"&MID(I23,8,4)&"-"&MID(I23,12,2)),IF(X23="CNPJ_INCOMPLETO_2",("00."&LEFT(I23,3)&"."&MID(I23,4,3)&"/"&MID(I23,7,4)&"-"&MID(I23,11,2)),IF(X23="CNPJ",(LEFT(I23,2)&"."&MID(I23,3,3)&"."&MID(I23,6,3)&"/"&MID(I23,9,4)&"-"&MID(I23,13,2)),IF(X23="CPF_Incompleto",("0"&LEFT(I23,2)&"."&MID(I23,3,3)&"."&MID(I23,6,3)&"-"&MID(I23,9,2)),(LEFT(I23,3)&"."&MID(I23,4,3)&"."&MID(I23,7,3)&"-"&MID(I23,10,2)))))) -> 966.856.970-91 | Z23: =VLOOKUP(Y23,FORNECEDORES!$A$2:$G$9043,3,0) -> DENIS CAMILLO DA SILVA | AA23: =VLOOKUP(Y23,FORNECEDORES!$A$2:$G$9041,7,0) -> deniscamillo29@gmail.com;
A24: CON:3481 | B24: 4417812015511030 | C24: 45839 | D24: 45841 | E24: SDO | F24: 661.64 | G24: EFETIVADA | H24: Denis Camillo Da Silva | I24: 96685697091 | J24: IQM9933 | K24: 101106138 | L24: SP | M24: 144558 | N24: 263557 | O24: 3481, 3482, 3483 | P24: RS | Q24: RS | R24: Finalizado | S24: Finalizada | T24: EFETIVADA | U24: Quinta feira | V24: Quinta feira | W24: =LEN(I24) -> 11 | X24: =IF(W24=14,"CNPJ",IF(W24=12,"CNPJ_INCOMPLETO_2",IF(W24=13,"CNPJ_INCOMPLETO_1",IF(W24=10,"CPF_Incompleto","CPF")))) -> CPF | Y24: =IF(X24="CNPJ_INCOMPLETO_1",("0"&LEFT(I24,1)&"."&MID(I24,2,3)&"."&MID(I24,5,3)&"/"&MID(I24,8,4)&"-"&MID(I24,12,2)),IF(X24="CNPJ_INCOMPLETO_2",("00."&LEFT(I24,3)&"."&MID(I24,4,3)&"/"&MID(I24,7,4)&"-"&MID(I24,11,2)),IF(X24="CNPJ",(LEFT(I24,2)&"."&MID(I24,3,3)&"."&MID(I24,6,3)&"/"&MID(I24,9,4)&"-"&MID(I24,13,2)),IF(X24="CPF_Incompleto",("0"&LEFT(I24,2)&"."&MID(I24,3,3)&"."&MID(I24,6,3)&"-"&MID(I24,9,2)),(LEFT(I24,3)&"."&MID(I24,4,3)&"."&MID(I24,7,3)&"-"&MID(I24,10,2)))))) -> 966.856.970-91 | Z24: =VLOOKUP(Y24,FORNECEDORES!$A$2:$G$9043,3,0) -> DENIS CAMILLO DA SILVA | AA24: =VLOOKUP(Y24,FORNECEDORES!$A$2:$G$9041,7,0) -> deniscamillo29@gmail.com;
A25: CON:3485 | B25: 4417812022858440 | C25: 45839 | D25: 45839 | E25: ADT | F25: 437.85 | G25: EFETIVADA | H25: JOSE DAGOBERTO MACHADO | I25: 40573680000 | J25: IKV8F25 | K25: 101116326 | L25: SP | M25: 144588 | N25: 263602 | O25: 3485 | P25: RS | Q25: RS | R25: Finalizado | S25: Finalizada | T25: EFETIVADA | U25: Quinta feira | V25: Quinta feira | W25: =LEN(I25) -> 11 | X25: =IF(W25=14,"CNPJ",IF(W25=12,"CNPJ_INCOMPLETO_2",IF(W25=13,"CNPJ_INCOMPLETO_1",IF(W25=10,"CPF_Incompleto","CPF")))) -> CPF | Y25: =IF(X25="CNPJ_INCOMPLETO_1",("0"&LEFT(I25,1)&"."&MID(I25,2,3)&"."&MID(I25,5,3)&"/"&MID(I25,8,4)&"-"&MID(I25,12,2)),IF(X25="CNPJ_INCOMPLETO_2",("00."&LEFT(I25,3)&"."&MID(I25,4,3)&"/"&MID(I25,7,4)&"-"&MID(I25,11,2)),IF(X25="CNPJ",(LEFT(I25,2)&"."&MID(I25,3,3)&"."&MID(I25,6,3)&"/"&MID(I25,9,4)&"-"&MID(I25,13,2)),IF(X25="CPF_Incompleto",("0"&LEFT(I25,2)&"."&MID(I25,3,3)&"."&MID(I25,6,3)&"-"&MID(I25,9,2)),(LEFT(I25,3)&"."&MID(I25,4,3)&"."&MID(I25,7,3)&"-"&MID(I25,10,2)))))) -> 405.736.800-00 | Z25: =VLOOKUP(Y25,FORNECEDORES!$A$2:$G$9043,3,0) -> JOSÉ DAGOBERTO MACHADO | AA25: =VLOOKUP(Y25,FORNECEDORES!$A$2:$G$9041,7,0) -> jdmdago@gmail.com;
A26: CON:3485 | B26: 4417812022858440 | C26: 45839 | D26: 45841 | E26: SDO | F26: 291.9 | G26: EFETIVADA | H26: JOSE DAGOBERTO MACHADO | I26: 40573680000 | J26: IKV8F25 | K26: 101116326 | L26: SP | M26: 144588 | N26: 263602 | O26: 3485 | P26: RS | Q26: RS | R26: Finalizado | S26: Finalizada | T26: EFETIVADA | U26: Quinta feira | V26: Quinta feira | W26: =LEN(I26) -> 11 | X26: =IF(W26=14,"CNPJ",IF(W26=12,"CNPJ_INCOMPLETO_2",IF(W26=13,"CNPJ_INCOMPLETO_1",IF(W26=10,"CPF_Incompleto","CPF")))) -> CPF | Y26: =IF(X26="CNPJ_INCOMPLETO_1",("0"&LEFT(I26,1)&"."&MID(I26,2,3)&"."&MID(I26,5,3)&"/"&MID(I26,8,4)&"-"&MID(I26,12,2)),IF(X26="CNPJ_INCOMPLETO_2",("00."&LEFT(I26,3)&"."&MID(I26,4,3)&"/"&MID(I26,7,4)&"-"&MID(I26,11,2)),IF(X26="CNPJ",(LEFT(I26,2)&"."&MID(I26,3,3)&"."&MID(I26,6,3)&"/"&MID(I26,9,4)&"-"&MID(I26,13,2)),IF(X26="CPF_Incompleto",("0"&LEFT(I26,2)&"."&MID(I26,3,3)&"."&MID(I26,6,3)&"-"&MID(I26,9,2)),(LEFT(I26,3)&"."&MID(I26,4,3)&"."&MID(I26,7,3)&"-"&MID(I26,10,2)))))) -> 405.736.800-00 | Z26: =VLOOKUP(Y26,FORNECEDORES!$A$2:$G$9043,3,0) -> JOSÉ DAGOBERTO MACHADO | AA26: =VLOOKUP(Y26,FORNECEDORES!$A$2:$G$9041,7,0) -> jdmdago@gmail.com;
A27: CON:3487 | B27: 4417812010875943 | C27: 45840 | D27: 45870 | E27: DES | F27: 1800 | G27: EFETIVADA | H27: ANDRE L.A. ENDRES - ME | I27: 92309194000120 | J27: AFK2804 | K27: 101141168 | L27: SP | M27: 144630 | N27: 263674 | O27: 3487 | P27: RS | Q27: RS | R27: Aprovado | S27: Em Transporte | T27: EFETIVADA | U27: 30 | V27: 45879 | W27: =LEN(I27) -> 14 | X27: =IF(W27=14,"CNPJ",IF(W27=12,"CNPJ_INCOMPLETO_2",IF(W27=13,"CNPJ_INCOMPLETO_1",IF(W27=10,"CPF_Incompleto","CPF")))) -> CNPJ | Y27: =IF(X27="CNPJ_INCOMPLETO_1",("0"&LEFT(I27,1)&"."&MID(I27,2,3)&"."&MID(I27,5,3)&"/"&MID(I27,8,4)&"-"&MID(I27,12,2)),IF(X27="CNPJ_INCOMPLETO_2",("00."&LEFT(I27,3)&"."&MID(I27,4,3)&"/"&MID(I27,7,4)&"-"&MID(I27,11,2)),IF(X27="CNPJ",(LEFT(I27,2)&"."&MID(I27,3,3)&"."&MID(I27,6,3)&"/"&MID(I27,9,4)&"-"&MID(I27,13,2)),IF(X27="CPF_Incompleto",("0"&LEFT(I27,2)&"."&MID(I27,3,3)&"."&MID(I27,6,3)&"-"&MID(I27,9,2)),(LEFT(I27,3)&"."&MID(I27,4,3)&"."&MID(I27,7,3)&"-"&MID(I27,10,2)))))) -> 92.309.194/0001-20 | Z27: =VLOOKUP(Y27,FORNECEDORES!$A$2:$G$9043,3,0) -> ANDRE L.A. ENDRES - ME | AA27: =VLOOKUP(Y27,FORNECEDORES!$A$2:$G$9041,7,0) -> endrestransportes@outlook.com
A28: CON:3489 | B28: 4417812013265605 | C28: 45840 | D28: 45841 | E28: ADT | F28: 1050.84 | G28: EFETIVADA | H28: VANDERLI DASSOLER | I28: 58751050030 | J28: MKS4A50 | K28: 101163718 | L28: SP | M28: 144665 | N28: 263744 | O28: 3489 | P28: RS | Q28: RS | R28: Finalizado | S28: Finalizada | T28: EFETIVADA | U28: Quinta feira | V28: Quinta feira | W28: =LEN(I28) -> 11 | X28: =IF(W28=14,"CNPJ",IF(W28=12,"CNPJ_INCOMPLETO_2",IF(W28=13,"CNPJ_INCOMPLETO_1",IF(W28=10,"CPF_Incompleto","CPF")))) -> CPF | Y28: =IF(X28="CNPJ_INCOMPLETO_1",("0"&LEFT(I28,1)&"."&MID(I28,2,3)&"."&MID(I28,5,3)&"/"&MID(I28,8,4)&"-"&MID(I28,12,2)),IF(X28="CNPJ_INCOMPLETO_2",("00."&LEFT(I28,3)&"."&MID(I28,4,3)&"/"&MID(I28,7,4)&"-"&MID(I28,11,2)),IF(X28="CNPJ",(LEFT(I28,2)&"."&MID(I28,3,3)&"."&MID(I28,6,3)&"/"&MID(I28,9,4)&"-"&MID(I28,13,2)),IF(X28="CPF_Incompleto",("0"&LEFT(I28,2)&"."&MID(I28,3,3)&"."&MID(I28,6,3)&"-"&MID(I28,9,2)),(LEFT(I28,3)&"."&MID(I28,4,3)&"."&MID(I28,7,3)&"-"&MID(I28,10,2)))))) -> 587.510.500-30 | Z28: =VLOOKUP(Y28,FORNECEDORES!$A$2:$G$9043,3,0) -> VANDERLI DASSOLER | AA28: =VLOOKUP(Y28,FORNECEDORES!$A$2:$G$9041,7,0) -> vanderliegv@gmail.com;
A29: CON:3489 | B29: 4417812013265605 | C29: 45840 | D29: 45841 | E29: SDO | F29: 700.56 | G29: EFETIVADA | H29: VANDERLI DASSOLER | I29: 58751050030 | J29: MKS4A50 | K29: 101163718 | L29: SP | M29: 144665 | N29: 263744 | O29: 3489 | P29: RS | Q29: RS | R29: Finalizado | S29: Finalizada | T29: EFETIVADA | U29: Quinta feira | V29: Quinta feira | W29: =LEN(I29) -> 11 | X29: =IF(W29=14,"CNPJ",IF(W29=12,"CNPJ_INCOMPLETO_2",IF(W29=13,"CNPJ_INCOMPLETO_1",IF(W29=10,"CPF_Incompleto","CPF")))) -> CPF | Y29: =IF(X29="CNPJ_INCOMPLETO_1",("0"&LEFT(I29,1)&"."&MID(I29,2,3)&"."&MID(I29,5,3)&"/"&MID(I29,8,4)&"-"&MID(I29,12,2)),IF(X29="CNPJ_INCOMPLETO_2",("00."&LEFT(I29,3)&"."&MID(I29,4,3)&"/"&MID(I29,7,4)&"-"&MID(I29,11,2)),IF(X29="CNPJ",(LEFT(I29,2)&"."&MID(I29,3,3)&"."&MID(I29,6,3)&"/"&MID(I29,9,4)&"-"&MID(I29,13,2)),IF(X29="CPF_Incompleto",("0"&LEFT(I29,2)&"."&MID(I29,3,3)&"."&MID(I29,6,3)&"-"&MID(I29,9,2)),(LEFT(I29,3)&"."&MID(I29,4,3)&"."&MID(I29,7,3)&"-"&MID(I29,10,2)))))) -> 587.510.500-30 | Z29: =VLOOKUP(Y29,FORNECEDORES!$A$2:$G$9043,3,0) -> VANDERLI DASSOLER | AA29: =VLOOKUP(Y29,FORNECEDORES!$A$2:$G$9041,7,0) -> vanderliegv@gmail.com;
A30: CON:3490 | B30: 4417812022858440 | C30: 45841 | D30: 45841 | E30: ADT | F30: 1576.26 | G30: EFETIVADA | H30: JOSE DAGOBERTO MACHADO | I30: 40573680000 | J30: IKV8F25 | K30: 101180167 | L30: SP | M30: 144691 | N30: 263792 | O30: 3490 | P30: RS | Q30: RS | R30: Finalizado | S30: Finalizada | T30: EFETIVADA | U30: Quinta feira | V30: Quinta feira | W30: =LEN(I30) -> 11 | X30: =IF(W30=14,"CNPJ",IF(W30=12,"CNPJ_INCOMPLETO_2",IF(W30=13,"CNPJ_INCOMPLETO_1",IF(W30=10,"CPF_Incompleto","CPF")))) -> CPF | Y30: =IF(X30="CNPJ_INCOMPLETO_1",("0"&LEFT(I30,1)&"."&MID(I30,2,3)&"."&MID(I30,5,3)&"/"&MID(I30,8,4)&"-"&MID(I30,12,2)),IF(X30="CNPJ_INCOMPLETO_2",("00."&LEFT(I30,3)&"."&MID(I30,4,3)&"/"&MID(I30,7,4)&"-"&MID(I30,11,2)),IF(X30="CNPJ",(LEFT(I30,2)&"."&MID(I30,3,3)&"."&MID(I30,6,3)&"/"&MID(I30,9,4)&"-"&MID(I30,13,2)),IF(X30="CPF_Incompleto",("0"&LEFT(I30,2)&"."&MID(I30,3,3)&"."&MID(I30,6,3)&"-"&MID(I30,9,2)),(LEFT(I30,3)&"."&MID(I30,4,3)&"."&MID(I30,7,3)&"-"&MID(I30,10,2)))))) -> 405.736.800-00 | Z30: =VLOOKUP(Y30,FORNECEDORES!$A$2:$G$9043,3,0) -> JOSÉ DAGOBERTO MACHADO | AA30: =VLOOKUP(Y30,FORNECEDORES!$A$2:$G$9041,7,0) -> jdmdago@gmail.com;
A31: CON:3490 | B31: 4417812022858440 | C31: 45841 | D31: 45841 | E31: SDO | F31: 1050.84 | G31: EFETIVADA | H31: JOSE DAGOBERTO MACHADO | I31: 40573680000 | J31: IKV8F25 | K31: 101180167 | L31: SP | M31: 144691 | N31: 263792 | O31: 3490 | P31: RS | Q31: RS | R31: Finalizado | S31: Finalizada | T31: EFETIVADA | U31: Quinta feira | V31: Quinta feira | W31: =LEN(I31) -> 11 | X31: =IF(W31=14,"CNPJ",IF(W31=12,"CNPJ_INCOMPLETO_2",IF(W31=13,"CNPJ_INCOMPLETO_1",IF(W31=10,"CPF_Incompleto","CPF")))) -> CPF | Y31: =IF(X31="CNPJ_INCOMPLETO_1",("0"&LEFT(I31,1)&"."&MID(I31,2,3)&"."&MID(I31,5,3)&"/"&MID(I31,8,4)&"-"&MID(I31,12,2)),IF(X31="CNPJ_INCOMPLETO_2",("00."&LEFT(I31,3)&"."&MID(I31,4,3)&"/"&MID(I31,7,4)&"-"&MID(I31,11,2)),IF(X31="CNPJ",(LEFT(I31,2)&"."&MID(I31,3,3)&"."&MID(I31,6,3)&"/"&MID(I31,9,4)&"-"&MID(I31,13,2)),IF(X31="CPF_Incompleto",("0"&LEFT(I31,2)&"."&MID(I31,3,3)&"."&MID(I31,6,3)&"-"&MID(I31,9,2)),(LEFT(I31,3)&"."&MID(I31,4,3)&"."&MID(I31,7,3)&"-"&MID(I31,10,2)))))) -> 405.736.800-00 | Z31: =VLOOKUP(Y31,FORNECEDORES!$A$2:$G$9043,3,0) -> JOSÉ DAGOBERTO MACHADO | AA31: =VLOOKUP(Y31,FORNECEDORES!$A$2:$G$9041,7,0) -> jdmdago@gmail.com;
A32: CON:1680 | B32: 4417812010875943 | C32: 45841 | D32: 45870 | E32: DES | F32: 660 | G32: EFETIVADA | H32: ANDRE L.A. ENDRES - ME | I32: 92309194000120 | J32: AFK2804 | K32: 101184547 | L32: SP | M32: 144699 | N32: 263820 | O32: 1680 | P32: RS | Q32: RS | R32: Finalizado | S32: Finalizada | T32: EFETIVADA | U32: 30 | V32: 45879 | W32: =LEN(I32) -> 14 | X32: =IF(W32=14,"CNPJ",IF(W32=12,"CNPJ_INCOMPLETO_2",IF(W32=13,"CNPJ_INCOMPLETO_1",IF(W32=10,"CPF_Incompleto","CPF")))) -> CNPJ | Y32: =IF(X32="CNPJ_INCOMPLETO_1",("0"&LEFT(I32,1)&"."&MID(I32,2,3)&"."&MID(I32,5,3)&"/"&MID(I32,8,4)&"-"&MID(I32,12,2)),IF(X32="CNPJ_INCOMPLETO_2",("00."&LEFT(I32,3)&"."&MID(I32,4,3)&"/"&MID(I32,7,4)&"-"&MID(I32,11,2)),IF(X32="CNPJ",(LEFT(I32,2)&"."&MID(I32,3,3)&"."&MID(I32,6,3)&"/"&MID(I32,9,4)&"-"&MID(I32,13,2)),IF(X32="CPF_Incompleto",("0"&LEFT(I32,2)&"."&MID(I32,3,3)&"."&MID(I32,6,3)&"-"&MID(I32,9,2)),(LEFT(I32,3)&"."&MID(I32,4,3)&"."&MID(I32,7,3)&"-"&MID(I32,10,2)))))) -> 92.309.194/0001-20 | Z32: =VLOOKUP(Y32,FORNECEDORES!$A$2:$G$9043,3,0) -> ANDRE L.A. ENDRES - ME | AA32: =VLOOKUP(Y32,FORNECEDORES!$A$2:$G$9041,7,0) -> endrestransportes@outlook.com
A33: CON:3494 | B33: 4417812010875943 | C33: 45841 | D33: 45870 | E33: DES | F33: 1800 | G33: EFETIVADA | H33: ANDRE L.A. ENDRES - ME | I33: 92309194000120 | J33: AFK2804 | K33: 101197051 | L33: SP | M33: 144717 | N33: 263893 | O33: 3494 | P33: RS | Q33: RS | R33: Finalizado | S33: Finalizada | T33: EFETIVADA | U33: 30 | V33: 45879 | W33: =LEN(I33) -> 14 | X33: =IF(W33=14,"CNPJ",IF(W33=12,"CNPJ_INCOMPLETO_2",IF(W33=13,"CNPJ_INCOMPLETO_1",IF(W33=10,"CPF_Incompleto","CPF")))) -> CNPJ | Y33: =IF(X33="CNPJ_INCOMPLETO_1",("0"&LEFT(I33,1)&"."&MID(I33,2,3)&"."&MID(I33,5,3)&"/"&MID(I33,8,4)&"-"&MID(I33,12,2)),IF(X33="CNPJ_INCOMPLETO_2",("00."&LEFT(I33,3)&"."&MID(I33,4,3)&"/"&MID(I33,7,4)&"-"&MID(I33,11,2)),IF(X33="CNPJ",(LEFT(I33,2)&"."&MID(I33,3,3)&"."&MID(I33,6,3)&"/"&MID(I33,9,4)&"-"&MID(I33,13,2)),IF(X33="CPF_Incompleto",("0"&LEFT(I33,2)&"."&MID(I33,3,3)&"."&MID(I33,6,3)&"-"&MID(I33,9,2)),(LEFT(I33,3)&"."&MID(I33,4,3)&"."&MID(I33,7,3)&"-"&MID(I33,10,2)))))) -> 92.309.194/0001-20 | Z33: =VLOOKUP(Y33,FORNECEDORES!$A$2:$G$9043,3,0) -> ANDRE L.A. ENDRES - ME | AA33: =VLOOKUP(Y33,FORNECEDORES!$A$2:$G$9041,7,0) -> endrestransportes@outlook.com
A34: CON:3495 | B34: 4417812014686304 | C34: 45841 | D34: 45842 | E34: ADT | F34: 342 | G34: EFETIVADA | H34: SILVERIO DA SILVEIRA | I34: 17250059000130 | J34: ATL5J69 | K34: 101200614 | L34: SP | M34: 144722 | N34: 263902 | O34: 3495 | P34: RS | Q34: RS | R34: Finalizado | S34: Finalizada | T34: EFETIVADA | U34: Quinta feira | V34: Quinta feira | W34: =LEN(I34) -> 14 | X34: =IF(W34=14,"CNPJ",IF(W34=12,"CNPJ_INCOMPLETO_2",IF(W34=13,"CNPJ_INCOMPLETO_1",IF(W34=10,"CPF_Incompleto","CPF")))) -> CNPJ | Y34: =IF(X34="CNPJ_INCOMPLETO_1",("0"&LEFT(I34,1)&"."&MID(I34,2,3)&"."&MID(I34,5,3)&"/"&MID(I34,8,4)&"-"&MID(I34,12,2)),IF(X34="CNPJ_INCOMPLETO_2",("00."&LEFT(I34,3)&"."&MID(I34,4,3)&"/"&MID(I34,7,4)&"-"&MID(I34,11,2)),IF(X34="CNPJ",(LEFT(I34,2)&"."&MID(I34,3,3)&"."&MID(I34,6,3)&"/"&MID(I34,9,4)&"-"&MID(I34,13,2)),IF(X34="CPF_Incompleto",("0"&LEFT(I34,2)&"."&MID(I34,3,3)&"."&MID(I34,6,3)&"-"&MID(I34,9,2)),(LEFT(I34,3)&"."&MID(I34,4,3)&"."&MID(I34,7,3)&"-"&MID(I34,10,2)))))) -> 17.250.059/0001-30 | Z34: =VLOOKUP(Y34,FORNECEDORES!$A$2:$G$9043,3,0) -> SILVERIO DA SILVEIRA ME | AA34: =VLOOKUP(Y34,FORNECEDORES!$A$2:$G$9041,7,0) -> silveriosilveira86@hotmail.com;
A35: CON:3495 | B35: 4417812014686304 | C35: 45841 | D35: 45848 | E35: SDO | F35: 228 | G35: EFETIVADA | H35: SILVERIO DA SILVEIRA | I35: 17250059000130 | J35: ATL5J69 | K35: 101200614 | L35: SP | M35: 144722 | N35: 263902 | O35: 3495 | P35: RS | Q35: RS | R35: Finalizado | S35: Finalizada | T35: EFETIVADA | U35: Quinta feira | V35: Quinta feira | W35: =LEN(I35) -> 14 | X35: =IF(W35=14,"CNPJ",IF(W35=12,"CNPJ_INCOMPLETO_2",IF(W35=13,"CNPJ_INCOMPLETO_1",IF(W35=10,"CPF_Incompleto","CPF")))) -> CNPJ | Y35: =IF(X35="CNPJ_INCOMPLETO_1",("0"&LEFT(I35,1)&"."&MID(I35,2,3)&"."&MID(I35,5,3)&"/"&MID(I35,8,4)&"-"&MID(I35,12,2)),IF(X35="CNPJ_INCOMPLETO_2",("00."&LEFT(I35,3)&"."&MID(I35,4,3)&"/"&MID(I35,7,4)&"-"&MID(I35,11,2)),IF(X35="CNPJ",(LEFT(I35,2)&"."&MID(I35,3,3)&"."&MID(I35,6,3)&"/"&MID(I35,9,4)&"-"&MID(I35,13,2)),IF(X35="CPF_Incompleto",("0"&LEFT(I35,2)&"."&MID(I35,3,3)&"."&MID(I35,6,3)&"-"&MID(I35,9,2)),(LEFT(I35,3)&"."&MID(I35,4,3)&"."&MID(I35,7,3)&"-"&MID(I35,10,2)))))) -> 17.250.059/0001-30 | Z35: =VLOOKUP(Y35,FORNECEDORES!$A$2:$G$9043,3,0) -> SILVERIO DA SILVEIRA ME | AA35: =VLOOKUP(Y35,FORNECEDORES!$A$2:$G$9041,7,0) -> silveriosilveira86@hotmail.com;
A36: CON:3496 | B36: 4417812015511030 | C36: 45841 | D36: 45842 | E36: ADT | F36: 1109.22 | G36: EFETIVADA | H36: Denis Camillo Da Silva | I36: 96685697091 | J36: IQM9933 | K36: 101206509 | L36: SP | M36: 144727 | N36: 263925 | O36: 3496 | P36: RS | Q36: RS | R36: Finalizado | S36: Finalizada | T36: EFETIVADA | U36: Quinta feira | V36: Quinta feira | W36: =LEN(I36) -> 11 | X36: =IF(W36=14,"CNPJ",IF(W36=12,"CNPJ_INCOMPLETO_2",IF(W36=13,"CNPJ_INCOMPLETO_1",IF(W36=10,"CPF_Incompleto","CPF")))) -> CPF | Y36: =IF(X36="CNPJ_INCOMPLETO_1",("0"&LEFT(I36,1)&"."&MID(I36,2,3)&"."&MID(I36,5,3)&"/"&MID(I36,8,4)&"-"&MID(I36,12,2)),IF(X36="CNPJ_INCOMPLETO_2",("00."&LEFT(I36,3)&"."&MID(I36,4,3)&"/"&MID(I36,7,4)&"-"&MID(I36,11,2)),IF(X36="CNPJ",(LEFT(I36,2)&"."&MID(I36,3,3)&"."&MID(I36,6,3)&"/"&MID(I36,9,4)&"-"&MID(I36,13,2)),IF(X36="CPF_Incompleto",("0"&LEFT(I36,2)&"."&MID(I36,3,3)&"."&MID(I36,6,3)&"-"&MID(I36,9,2)),(LEFT(I36,3)&"."&MID(I36,4,3)&"."&MID(I36,7,3)&"-"&MID(I36,10,2)))))) -> 966.856.970-91 | Z36: =VLOOKUP(Y36,FORNECEDORES!$A$2:$G$9043,3,0) -> DENIS CAMILLO DA SILVA | AA36: =VLOOKUP(Y36,FORNECEDORES!$A$2:$G$9041,7,0) -> deniscamillo29@gmail.com;
A37: CON:3496 | B37: 4417812015511030 | C37: 45841 | D37: 45848 | E37: SDO | F37: 739.48 | G37: EFETIVADA | H37: Denis Camillo Da Silva | I37: 96685697091 | J37: IQM9933 | K37: 101206509 | L37: SP | M37: 144727 | N37: 263925 | O37: 3496 | P37: RS | Q37: RS | R37: Finalizado | S37: Finalizada | T37: EFETIVADA | U37: Quinta feira | V37: Quinta feira | W37: =LEN(I37) -> 11 | X37: =IF(W37=14,"CNPJ",IF(W37=12,"CNPJ_INCOMPLETO_2",IF(W37=13,"CNPJ_INCOMPLETO_1",IF(W37=10,"CPF_Incompleto","CPF")))) -> CPF | Y37: =IF(X37="CNPJ_INCOMPLETO_1",("0"&LEFT(I37,1)&"."&MID(I37,2,3)&"."&MID(I37,5,3)&"/"&MID(I37,8,4)&"-"&MID(I37,12,2)),IF(X37="CNPJ_INCOMPLETO_2",("00."&LEFT(I37,3)&"."&MID(I37,4,3)&"/"&MID(I37,7,4)&"-"&MID(I37,11,2)),IF(X37="CNPJ",(LEFT(I37,2)&"."&MID(I37,3,3)&"."&MID(I37,6,3)&"/"&MID(I37,9,4)&"-"&MID(I37,13,2)),IF(X37="CPF_Incompleto",("0"&LEFT(I37,2)&"."&MID(I37,3,3)&"."&MID(I37,6,3)&"-"&MID(I37,9,2)),(LEFT(I37,3)&"."&MID(I37,4,3)&"."&MID(I37,7,3)&"-"&MID(I37,10,2)))))) -> 966.856.970-91 | Z37: =VLOOKUP(Y37,FORNECEDORES!$A$2:$G$9043,3,0) -> DENIS CAMILLO DA SILVA | AA37: =VLOOKUP(Y37,FORNECEDORES!$A$2:$G$9041,7,0) -> deniscamillo29@gmail.com;
A38: CON:3497 | B38: 4417812013265605 | C38: 45841 | D38: 45842 | E38: ADT | F38: 1576.26 | G38: EFETIVADA | H38: VANDERLI DASSOLER | I38: 58751050030 | J38: MKS4A50 | K38: 101207475 | L38: SP | M38: 144730 | N38: 263933 | O38: 3497 | P38: RS | Q38: RS | R38: Finalizado | S38: Finalizada | T38: EFETIVADA | U38: Quinta feira | V38: Quinta feira | W38: =LEN(I38) -> 11 | X38: =IF(W38=14,"CNPJ",IF(W38=12,"CNPJ_INCOMPLETO_2",IF(W38=13,"CNPJ_INCOMPLETO_1",IF(W38=10,"CPF_Incompleto","CPF")))) -> CPF | Y38: =IF(X38="CNPJ_INCOMPLETO_1",("0"&LEFT(I38,1)&"."&MID(I38,2,3)&"."&MID(I38,5,3)&"/"&MID(I38,8,4)&"-"&MID(I38,12,2)),IF(X38="CNPJ_INCOMPLETO_2",("00."&LEFT(I38,3)&"."&MID(I38,4,3)&"/"&MID(I38,7,4)&"-"&MID(I38,11,2)),IF(X38="CNPJ",(LEFT(I38,2)&"."&MID(I38,3,3)&"."&MID(I38,6,3)&"/"&MID(I38,9,4)&"-"&MID(I38,13,2)),IF(X38="CPF_Incompleto",("0"&LEFT(I38,2)&"."&MID(I38,3,3)&"."&MID(I38,6,3)&"-"&MID(I38,9,2)),(LEFT(I38,3)&"."&MID(I38,4,3)&"."&MID(I38,7,3)&"-"&MID(I38,10,2)))))) -> 587.510.500-30 | Z38: =VLOOKUP(Y38,FORNECEDORES!$A$2:$G$9043,3,0) -> VANDERLI DASSOLER | AA38: =VLOOKUP(Y38,FORNECEDORES!$A$2:$G$9041,7,0) -> vanderliegv@gmail.com;
A39: CON:3497 | B39: 4417812013265605 | C39: 45841 | D39: 45848 | E39: SDO | F39: 1050.84 | G39: EFETIVADA | H39: VANDERLI DASSOLER | I39: 58751050030 | J39: MKS4A50 | K39: 101207475 | L39: SP | M39: 144730 | N39: 263933 | O39: 3497 | P39: RS | Q39: RS | R39: Finalizado | S39: Finalizada | T39: EFETIVADA | U39: Quinta feira | V39: Quinta feira | W39: =LEN(I39) -> 11 | X39: =IF(W39=14,"CNPJ",IF(W39=12,"CNPJ_INCOMPLETO_2",IF(W39=13,"CNPJ_INCOMPLETO_1",IF(W39=10,"CPF_Incompleto","CPF")))) -> CPF | Y39: =IF(X39="CNPJ_INCOMPLETO_1",("0"&LEFT(I39,1)&"."&MID(I39,2,3)&"."&MID(I39,5,3)&"/"&MID(I39,8,4)&"-"&MID(I39,12,2)),IF(X39="CNPJ_INCOMPLETO_2",("00."&LEFT(I39,3)&"."&MID(I39,4,3)&"/"&MID(I39,7,4)&"-"&MID(I39,11,2)),IF(X39="CNPJ",(LEFT(I39,2)&"."&MID(I39,3,3)&"."&MID(I39,6,3)&"/"&MID(I39,9,4)&"-"&MID(I39,13,2)),IF(X39="CPF_Incompleto",("0"&LEFT(I39,2)&"."&MID(I39,3,3)&"."&MID(I39,6,3)&"-"&MID(I39,9,2)),(LEFT(I39,3)&"."&MID(I39,4,3)&"."&MID(I39,7,3)&"-"&MID(I39,10,2)))))) -> 587.510.500-30 | Z39: =VLOOKUP(Y39,FORNECEDORES!$A$2:$G$9043,3,0) -> VANDERLI DASSOLER | AA39: =VLOOKUP(Y39,FORNECEDORES!$A$2:$G$9041,7,0) -> vanderliegv@gmail.com;
A40: CON:3499 | B40: 4417812014686304 | C40: 45842 | D40: 45842 | E40: ADT | F40: 1020 | G40: EFETIVADA | H40: SILVERIO DA SILVEIRA | I40: 17250059000130 | J40: ATL5J69 | K40: 101223195 | L40: SP | M40: 144760 | N40: 263972 | O40: 3499, 3500 | P40: RS | Q40: RS | R40: Finalizado | S40: Finalizada | T40: EFETIVADA | U40: Quinta feira | V40: Quinta feira | W40: =LEN(I40) -> 14 | X40: =IF(W40=14,"CNPJ",IF(W40=12,"CNPJ_INCOMPLETO_2",IF(W40=13,"CNPJ_INCOMPLETO_1",IF(W40=10,"CPF_Incompleto","CPF")))) -> CNPJ | Y40: =IF(X40="CNPJ_INCOMPLETO_1",("0"&LEFT(I40,1)&"."&MID(I40,2,3)&"."&MID(I40,5,3)&"/"&MID(I40,8,4)&"-"&MID(I40,12,2)),IF(X40="CNPJ_INCOMPLETO_2",("00."&LEFT(I40,3)&"."&MID(I40,4,3)&"/"&MID(I40,7,4)&"-"&MID(I40,11,2)),IF(X40="CNPJ",(LEFT(I40,2)&"."&MID(I40,3,3)&"."&MID(I40,6,3)&"/"&MID(I40,9,4)&"-"&MID(I40,13,2)),IF(X40="CPF_Incompleto",("0"&LEFT(I40,2)&"."&MID(I40,3,3)&"."&MID(I40,6,3)&"-"&MID(I40,9,2)),(LEFT(I40,3)&"."&MID(I40,4,3)&"."&MID(I40,7,3)&"-"&MID(I40,10,2)))))) -> 17.250.059/0001-30 | Z40: =VLOOKUP(Y40,FORNECEDORES!$A$2:$G$9043,3,0) -> SILVERIO DA SILVEIRA ME | AA40: =VLOOKUP(Y40,FORNECEDORES!$A$2:$G$9041,7,0) -> silveriosilveira86@hotmail.com;
...

Sheet verificar1
A1: Nome do Favorecido | B1: Documento do Favorecido | C1: Placa do veículo | D1: ID Viagem | E1: Filial | F1: Contrato de Frete | G1: Carga | H1: OBS | M1: Nome do Favorecido | N1: Placa do veículo | O1: Contrato de Frete | P1: Carga | Q1: OBS
A2: EBERTON EDUARDO ALVES | B2: 33924768897 | C2: JSN1D79 | D2: 104029305 | E2: SP | F2: 148828 | G2: 273564 | H2: logistica.onix@gmail.com | M2: EBERTON EDUARDO ALVES | N2: JSN1D79 | O2: 148828 | P2: 273564 | Q2: logistica.onix@gmail.com
A3: EBERTON EDUARDO ALVES | B3: 33924768897 | C3: JSN1D79 | D3: 104029305 | E3: SP | F3: 148828 | G3: 273564 | H3: logistica.onix@gmail.com | M3: EBERTON EDUARDO ALVES | N3: JSN1D79 | O3: 148828 | P3: 273564 | Q3: logistica.onix@gmail.com
A4: LUIS CAIO OLIVEIRA DOS SANTOS | B4: 6786288588 | C4: MLF7B49 | D4: 104069155 | E4: SP | F4: 148768 | G4: 273461 | H4: luiscaio1620@gmail.com; | M4: LUIS CAIO OLIVEIRA DOS SANTOS | N4: MLF7B49 | O4: 148768 | P4: 273461 | Q4: luiscaio1620@gmail.com;
A5: LUIS CAIO OLIVEIRA DOS SANTOS | B5: 6786288588 | C5: MLF7B49 | D5: 104069155 | E5: SP | F5: 148768 | G5: 273461 | H5: luiscaio1620@gmail.com; | M5: LUIS CAIO OLIVEIRA DOS SANTOS | N5: MLF7B49 | O5: 148768 | P5: 273461 | Q5: luiscaio1620@gmail.com;
A6: FAGNER MARQUES LUCAS | B6: 29773789870 | C6: PRQ9B73 | D6: 104069220 | E6: SP | F6: 148899 | G6: 273750 | H6: fag.125k@gmail.com; | M6: FAGNER MARQUES LUCAS | N6: PRQ9B73 | O6: 148899 | P6: 273750 | Q6: fag.125k@gmail.com;
A7: FAGNER MARQUES LUCAS | B7: 29773789870 | C7: PRQ9B73 | D7: 104069220 | E7: SP | F7: 148899 | G7: 273750 | H7: fag.125k@gmail.com; | M7: FAGNER MARQUES LUCAS | N7: PRQ9B73 | O7: 148899 | P7: 273750 | Q7: fag.125k@gmail.com;
A8: Diego Thales Lopes Cançado | B8: 8791702631 | C8: OZH6G24 | D8: 104069384 | E8: SP | F8: 148904 | G8: 273778 | H8: CADASTRADO SEM E-MAIL | M8: Diego Thales Lopes Cançado | N8: OZH6G24 | O8: 148904 | P8: 273778 | Q8: CADASTRADO SEM E-MAIL
A9: Diego Thales Lopes Cançado | B9: 8791702631 | C9: OZH6G24 | D9: 104069384 | E9: SP | F9: 148904 | G9: 273778 | H9: CADASTRADO SEM E-MAIL | M9: Diego Thales Lopes Cançado | N9: OZH6G24 | O9: 148904 | P9: 273778 | Q9: CADASTRADO SEM E-MAIL
M13: Nome do Favorecido | N13: Placa do veículo | O13: Contrato de Frete | P13: Carga | Q13: OBS
M14: EBERTON EDUARDO ALVES | N14: JSN1D79 | O14: 148828 | P14: 273564 | Q14: CADASTRADO SEM E-MAIL
M15: Diego Thales Lopes Cançado | N15: OZH6G24 | O15: 148904 | P15: 273778 | Q15: CADASTRADO SEM E-MAIL

Sheet verificar
B1: REFERENCIA | C1: PRESTADOR
B2: 050.253.025-10 | C2: LEANDRO DE JESUS MENDONCA
B3: 215.407.458-80 | C3: CINTIA ANTUNES NASCIMENTO
B4: 184.250.368-52 | C4: QUEILA DIANE ROMAGNOLI RODRIGUES
B5: 334.143.418-67 | C5: IDALECIO FIRMINO DE OLIVEIRA
B6: 477.928.638-75 | C6: ANDRESSA BISPO RAMOS

Sheet FORNECEDORES
A1: CNPJ | B1: COD_TR | C1: NOME_TRANSPORTADORA | D1: NOME_FANTASIA | E1: RESPONSÁVEL | F1: Tel_Fixo | G1: E-mail | H1: E-mail 2 | I1: MONITOR | J1: Ativa | K1: Analista | L1: Ativar | M1: Logo | N1: UF | O1: Foto | P1: Parceiro | Q1: ENDERECO | R1: MUNICIPIO | S1: CEP | T1: CNPJ | U1: INCRICAO_ESTADUAL | V1: Tipo de Carga | W1: VUC PLATAFORMA | X1: VUC | Y1: LEVE SECO | Z1: LEVE SECO PLATAFORMA | AA1: LEVE REFRIGERADO | AB1: TOCO SECO | AC1: TOCO SECO PLATAFORMA | AD1: TOCO REFRIGERADO | AE1: TRUCK SECO | AF1: TRUCK SECO PLATAFORMA | AG1: TRUCK REFRIGERADA | AH1: CARRETA SECA | AI1: CARRETA SECA PLATAFORMA | AJ1: CARRETA REFRIGERADA | AK1: AC | AL1: AL | AM1: AM | AN1: AP | AO1: BA | AP1: CE | AQ1: DF | AR1: ES | AS1: GO | AT1: MA | AU1: MG | AV1: MS | AW1: MT | AX1: PA | AY1: PB | AZ1: PE | BA1: PI | BB1: PR | BC1: RJ | BD1: RN | BE1: RO | BF1: RR | BG1: RS | BH1: SC | BI1: SE | BJ1: SP | BK1: TO | BL1: Data_Cadastro | BM1: CÓD
A2: 10.948.789/0001-60 | B2: 10948789 | C2: TRANSRIMA TRANSPORTES | D2: TRANSRIMA TRANSPORTES | E2: RICARDO | F2: 49 99928-8382 | G2: ricardo@transrima.com.br; | J2: FALSE | K2: FABIO ALVES CORDEIRO | L2: TRUE | N2: SC | P2: FALSE | Q2: TRAVESSA FAVASSA, 54 - SALA1 - BAIRRO IMPERIAL - CONCORDIA - SC | R2: CONCORDIA | S2: 89709-010 | T2: 10.948.789/0001-60 | U2: 255891210 | W2: FALSE | X2: FALSE | Y2: FALSE | Z2: FALSE | AA2: FALSE | AB2: FALSE | AC2: FALSE | AD2: FALSE | AE2: FALSE | AF2: FALSE | AG2: FALSE | AH2: FALSE | AI2: FALSE | AJ2: FALSE | AK2: FALSE | AL2: FALSE | AM2: FALSE | AN2: FALSE | AO2: FALSE | AP2: FALSE | AQ2: FALSE | AR2: FALSE | AS2: FALSE | AT2: FALSE | AU2: FALSE | AV2: FALSE | AW2: FALSE | AX2: FALSE | AY2: FALSE | AZ2: FALSE | BA2: FALSE | BB2: FALSE | BC2: FALSE | BD2: FALSE | BE2: FALSE | BF2: FALSE | BG2: FALSE | BH2: FALSE | BI2: FALSE | BJ2: FALSE | BK2: FALSE | BL2: 45807.741 | BM2: 1275
A3: 63.073.266/0020-47 | B3: 63073266 | C3: TRANSPORTADORA BOMPREÇO LTDA | D3: BOMPREÇO | E3: PABLO SARMENTO | F3: 11-954567877 | G3: fabio_cordeiro@carrefour.com; | J3: FALSE | K3: FABIO ALVES CORDEIRO | L3: TRUE | N3: SP | P3: FALSE | T3: 63.073.266/0020-47 | U3: 241131272113 | W3: FALSE | X3: FALSE | Y3: FALSE | Z3: FALSE | AA3: FALSE | AB3: FALSE | AC3: FALSE | AD3: FALSE | AE3: FALSE | AF3: FALSE | AG3: FALSE | AH3: FALSE | AI3: FALSE | AJ3: FALSE | AK3: FALSE | AL3: FALSE | AM3: FALSE | AN3: FALSE | AO3: FALSE | AP3: FALSE | AQ3: FALSE | AR3: FALSE | AS3: FALSE | AT3: FALSE | AU3: FALSE | AV3: FALSE | AW3: FALSE | AX3: FALSE | AY3: FALSE | AZ3: FALSE | BA3: FALSE | BB3: FALSE | BC3: FALSE | BD3: FALSE | BE3: FALSE | BF3: FALSE | BG3: FALSE | BH3: FALSE | BI3: FALSE | BJ3: FALSE | BK3: FALSE | BM3: 643
A4: 63.073.266/0004-27 | B4: 63073266000427 | C4: TRANSPORTADORA BOMPREÇO LTDA | D4: BOMPREÇO | E4: PABLO SARMENTO | F4: 11-954567877 | G4: fabio_cordeiro@carrefour.com; luiz_antonio_neris_dos_santos@carrefour.com | H4: NOVO | J4: FALSE | K4: FABIO ALVES CORDEIRO | L4: TRUE | N4: SP | P4: FALSE | Q4: AVENIDA RECIFE, 2 - JARDIM SANTO AFONSO (JARDIM PRESIDENTE DUTRA) - GUARULHOS - | R4: GUARULHOS | S4: 07.271-220 | T4: 63.073.266/0004-27 | U4: 241131272113 | W4: FALSE | X4: FALSE | Y4: FALSE | Z4: FALSE | AA4: FALSE | AB4: FALSE | AC4: FALSE | AD4: FALSE | AE4: FALSE | AF4: FALSE | AG4: FALSE | AH4: FALSE | AI4: FALSE | AJ4: FALSE | AK4: FALSE | AL4: FALSE | AM4: FALSE | AN4: FALSE | AO4: FALSE | AP4: FALSE | AQ4: FALSE | AR4: FALSE | AS4: FALSE | AT4: FALSE | AU4: FALSE | AV4: FALSE | AW4: FALSE | AX4: FALSE | AY4: FALSE | AZ4: FALSE | BA4: FALSE | BB4: FALSE | BC4: FALSE | BD4: FALSE | BE4: FALSE | BF4: FALSE | BG4: FALSE | BH4: FALSE | BI4: FALSE | BJ4: FALSE | BK4: FALSE | BL4: 45830.63 | BM4: 1304
A5: 63.073.266/0011-56 | B5: 63073266001156 | C5: TRANSPORTADORA BOMPREÇO LTDA | D5: BOMPREÇO | E5: PABLO SARMENTO | F5: 11-954567877 | G5: fabio_cordeiro@carrefour.com; luiz_antonio_neris_dos_santos@carrefour.com | H5: NOVO | J5: FALSE | K5: FABIO ALVES CORDEIRO | L5: TRUE | N5: SP | P5: FALSE | Q5: RUA SERGIO JUNGBLUT DIETERICH, 913 - SALAA - SARANDI - PORTO ALEGRE | RS | R5: PORTO ALEGRE | S5: 91060-410 | T5: 63.073.266/0011-56 | W5: FALSE | X5: FALSE | Y5: FALSE | Z5: FALSE | AA5: FALSE | AB5: FALSE | AC5: FALSE | AD5: FALSE | AE5: FALSE | AF5: FALSE | AG5: FALSE | AH5: FALSE | AI5: FALSE | AJ5: FALSE | AK5: FALSE | AL5: FALSE | AM5: FALSE | AN5: FALSE | AO5: FALSE | AP5: FALSE | AQ5: FALSE | AR5: FALSE | AS5: FALSE | AT5: FALSE | AU5: FALSE | AV5: FALSE | AW5: FALSE | AX5: FALSE | AY5: FALSE | AZ5: FALSE | BA5: FALSE | BB5: FALSE | BC5: FALSE | BD5: FALSE | BE5: FALSE | BF5: FALSE | BG5: FALSE | BH5: FALSE | BI5: FALSE | BJ5: FALSE | BK5: FALSE | BL5: 45830.636 | BM5: 1305
A6: 63.073.266/0023-90 | B6: 63073266002390 | C6: TRANSPORTADORA BOMPREÇO LTDA | D6: BOMPREÇO | E6: PABLO SARMENTO | F6: 11-954567877 | G6: fabio_cordeiro@carrefour.com; luiz_antonio_neris_dos_santos@carrefour.com | H6: NOVO | J6: FALSE | K6: FABIO ALVES CORDEIRO | L6: TRUE | N6: SP | P6: FALSE | T6: 63.073.266/0023-90 | U6: 241131272113 | W6: FALSE | X6: FALSE | Y6: FALSE | Z6: FALSE | AA6: FALSE | AB6: FALSE | AC6: FALSE | AD6: FALSE | AE6: FALSE | AF6: FALSE | AG6: FALSE | AH6: FALSE | AI6: FALSE | AJ6: FALSE | AK6: FALSE | AL6: FALSE | AM6: FALSE | AN6: FALSE | AO6: FALSE | AP6: FALSE | AQ6: FALSE | AR6: FALSE | AS6: FALSE | AT6: FALSE | AU6: FALSE | AV6: FALSE | AW6: FALSE | AX6: FALSE | AY6: FALSE | AZ6: FALSE | BA6: FALSE | BB6: FALSE | BC6: FALSE | BD6: FALSE | BE6: FALSE | BF6: FALSE | BG6: FALSE | BH6: FALSE | BI6: FALSE | BJ6: FALSE | BK6: FALSE | BL6: 45708.668 | BM6: 1234
A7: 63.073.266/0024-70 | B7: 6307326600239070 | C7: TRANSPORTADORA BOMPREÇO LTDA | D7: BOMPREÇO | E7: PABLO SARMENTO | F7: 11-954567877 | G7: fabio_cordeiro@carrefour.com; luiz_antonio_neris_dos_santos@carrefour.com | H7: NOVO | J7: FALSE | K7: FABIO ALVES CORDEIRO | L7: TRUE | N7: SP | P7: FALSE | Q7: AVENIDA DOUTOR MAURO LINDEMBERG MONTEIRO, 628 - KM 98 BLOCO A SUPERIOR SALA 1 - BAIRRO SANTA FE - OSASCO - SP | R7: OSASCO | S7: 0628-010 | T7: 63.073.266/0024-70 | U7: 241131272113 | W7: FALSE | X7: FALSE | Y7: FALSE | Z7: FALSE | AA7: FALSE | AB7: FALSE | AC7: FALSE | AD7: FALSE | AE7: FALSE | AF7: FALSE | AG7: FALSE | AH7: FALSE | AI7: FALSE | AJ7: FALSE | AK7: FALSE | AL7: FALSE | AM7: FALSE | AN7: FALSE | AO7: FALSE | AP7: FALSE | AQ7: FALSE | AR7: FALSE | AS7: FALSE | AT7: FALSE | AU7: FALSE | AV7: FALSE | AW7: FALSE | AX7: FALSE | AY7: FALSE | AZ7: FALSE | BA7: FALSE | BB7: FALSE | BC7: FALSE | BD7: FALSE | BE7: FALSE | BF7: FALSE | BG7: FALSE | BH7: FALSE | BI7: FALSE | BJ7: FALSE | BK7: FALSE | BL7: 45807.436 | BM7: 1267
A8: 80.424.914/0003-80 | B8: 80424914 | C8: TRANSPORTES TOZZO LTDA | D8: TRANSPORTES TOZZO LTDA | E8: SOLANGE | F8: 49 8805-9773 | G8: solange.oliveira@transtozzo.com.br; | J8: FALSE | K8: FABIO ALVES CORDEIRO | L8: TRUE | N8: SP | P8: FALSE | Q8: RODOVIA VICE-PREFEITO HERMENEGILDO TONOLLI, 2995 - SALA 01 - Bairro: DESMEMBRAMENTO SANTA CLARA - ITUPEVA - SP | R8: ITUPEVA | S8: 13295-504 | T8: 80.424.914/0003-80 | U8: 388.026.458.117 | W8: FALSE | X8: FALSE | Y8: FALSE | Z8: FALSE | AA8: FALSE | AB8: FALSE | AC8: FALSE | AD8: FALSE | AE8: FALSE | AF8: FALSE | AG8: FALSE | AH8: FALSE | AI8: FALSE | AJ8: FALSE | AK8: FALSE | AL8: FALSE | AM8: FALSE | AN8: FALSE | AO8: FALSE | AP8: FALSE | AQ8: FALSE | AR8: FALSE | AS8: FALSE | AT8: FALSE | AU8: FALSE | AV8: FALSE | AW8: FALSE | AX8: FALSE | AY8: FALSE | AZ8: FALSE | BA8: FALSE | BB8: FALSE | BC8: FALSE | BD8: FALSE | BE8: FALSE | BF8: FALSE | BG8: FALSE | BH8: FALSE | BI8: FALSE | BJ8: FALSE | BK8: FALSE | BL8: 45807.474 | BM8: 1272
A9: 80.424.914/0001-19 | B9: 80424914000119 | C9: TRANSPORTES TOZZO LTDA | D9: TRANSPORTES TOZZO LTDA | E9: SOLANGE | F9: 49 8805-9773 | G9: solange.oliveira@transtozzo.com.br; log5@transtozzo.com.br; | J9: FALSE | K9: FABIO ALVES CORDEIRO | L9: TRUE | N9: SC | P9: FALSE | Q9: ACESSO PLÍNIO ARLINDO DE NES, 4303-D - ACESSO BR 282 - BELVEDERE - CHAPECÓ - SC | R9: CHAPECO | S9: 89810-460 | T9: 80.424.914/0001-19 | U9: 251755738 | W9: FALSE | X9: FALSE | Y9: FALSE | Z9: FALSE | AA9: FALSE | AB9: FALSE | AC9: FALSE | AD9: FALSE | AE9: FALSE | AF9: FALSE | AG9: FALSE | AH9: FALSE | AI9: FALSE | AJ9: FALSE | AK9: FALSE | AL9: FALSE | AM9: FALSE | AN9: FALSE | AO9: FALSE | AP9: FALSE | AQ9: FALSE | AR9: FALSE | AS9: FALSE | AT9: FALSE | AU9: FALSE | AV9: FALSE | AW9: FALSE | AX9: FALSE | AY9: FALSE | AZ9: FALSE | BA9: FALSE | BB9: FALSE | BC9: FALSE | BD9: FALSE | BE9: FALSE | BF9: FALSE | BG9: FALSE | BH9: FALSE | BI9: FALSE | BJ9: FALSE | BK9: FALSE | BL9: 45841.441 | BM9: 1317
A10: 01.599.101/0001-93 | B10: 0159910 | C10: SEQUOIA LOGISTICA E TRANSPORTES S.A | D10: SEQUOIA LOGISTICA E TRANSPORTES S.A | E10: MOACIR - OPER / CLAUDIA -COM | F10: 11-983963646 / 31-99319-4980 | G10: moacir.giovanello@sequoialog.com.br; claudia.msilva@sequoialog.com.br ;nubia.prates@sequoialog.com.br; torre.trafego@sequoialog.com.br; | J10: FALSE | K10: FABIO ALVES CORDEIRO | L10: TRUE | N10: SP | P10: FALSE | Q10: AVENIDA ISALTINO VICTOR DE MORAES, 437 - TERREOMOD. D BLOCO 100 - VILA BONFIM - EMBU DAS ARTES - SP | R10: EMBU DAS ARTES | S10: 06.806-400 | T10: 01.599.101/0001-93 | U10: 298.078.404.118 | W10: FALSE | X10: FALSE | Y10: FALSE | Z10: FALSE | AA10: FALSE | AB10: FALSE | AC10: FALSE | AD10: FALSE | AE10: FALSE | AF10: FALSE | AG10: FALSE | AH10: TRUE | AI10: FALSE | AJ10: FALSE | AK10: FALSE | AL10: FALSE | AM10: FALSE | AN10: FALSE | AO10: FALSE | AP10: FALSE | AQ10: TRUE | AR10: FALSE | AS10: FALSE | AT10: FALSE | AU10: TRUE | AV10: FALSE | AW10: FALSE | AX10: FALSE | AY10: FALSE | AZ10: FALSE | BA10: FALSE | BB10: FALSE | BC10: TRUE | BD10: FALSE | BE10: FALSE | BF10: FALSE | BG10: FALSE | BH10: FALSE | BI10: FALSE | BJ10: TRUE | BK10: FALSE | BM10: 567
A11: 08.158.720/0002-72 | B11: 08158720 | C11: TRANSPORTADORA PEREGRINA LTDA | D11: TRANSPORTADORA PEREGRINA | E11: GABRIEL CECHINEL MACCARI | F11: 48-3467-2700 / 48 99903-0134 | G11: vendas03@transperegrina.com.br; gabriel@transperegrina.com.br; setor.vendas@transperegrina.com.br; olavo@transperegrina.com.br; | J11: FALSE | K11: FABIO ALVES CORDEIRO | L11: TRUE | N11: SP | P11: FALSE | Q11: AV 56, - ALTO DO SANTANA - RIO CLARO - SP - CEP:13504195 | R11: RIO CLARO | S11: 13504195 | T11: 08.158.720/0002-72 | U11: 587294177117 | W11: FALSE | X11: FALSE | Y11: FALSE | Z11: FALSE | AA11: FALSE | AB11: FALSE | AC11: FALSE | AD11: FALSE | AE11: FALSE | AF11: FALSE | AG11: FALSE | AH11: FALSE | AI11: FALSE | AJ11: FALSE | AK11: FALSE | AL11: FALSE | AM11: FALSE | AN11: FALSE | AO11: FALSE | AP11: FALSE | AQ11: FALSE | AR11: FALSE | AS11: FALSE | AT11: FALSE | AU11: FALSE | AV11: FALSE | AW11: FALSE | AX11: FALSE | AY11: FALSE | AZ11: FALSE | BA11: FALSE | BB11: FALSE | BC11: FALSE | BD11: FALSE | BE11: FALSE | BF11: FALSE | BG11: FALSE | BH11: FALSE | BI11: FALSE | BJ11: FALSE | BK11: FALSE | BM11: 677
A12: 60.077.336/0001-84 | B12: 60077336 | C12: JOB TRANSPORTES DE ITATIBA LTDA | D12: B J TRANSPORTES DE ITATIBA LTDA | F12: 11975930568 | H12: ANTT 00121203 | J12: FALSE | K12: FABIO ALVES CORDEIRO | L12: TRUE | N12: SP | P12: FALSE | Q12: AVENIDA ANTONIO NARDI, 777 - | R12: ITATIBA | S12: 13254260 | T12: 60.077.336/0001-84 | U12: 382031050117 | W12: FALSE | X12: FALSE | Y12: FALSE | Z12: FALSE | AA12: FALSE | AB12: FALSE | AC12: FALSE | AD12: FALSE | AE12: FALSE | AF12: FALSE | AG12: FALSE | AH12: FALSE | AI12: FALSE | AJ12: FALSE | AK12: FALSE | AL12: FALSE | AM12: FALSE | AN12: FALSE | AO12: FALSE | AP12: FALSE | AQ12: FALSE | AR12: FALSE | AS12: FALSE | AT12: FALSE | AU12: FALSE | AV12: FALSE | AW12: FALSE | AX12: FALSE | AY12: FALSE | AZ12: FALSE | BA12: FALSE | BB12: FALSE | BC12: FALSE | BD12: FALSE | BE12: FALSE | BF12: FALSE | BG12: FALSE | BH12: FALSE | BI12: FALSE | BJ12: FALSE | BK12: FALSE | BM12: 653
